Workbook

Sheet README
A1: README — Deer Velvet Quarantine Dataset, Korea (2019–2026)
A2: Last updated: 2026-07-20 (v3, final — includes Deer velvet extract)
A4: PURPOSE
A5: Consolidated import/export quarantine statistics for deer velvet products (녹용/생녹용/녹용추출물) in Korea, from official QIA statistics.
A7: SHEET GUIDE
A8: • Flat Data — machine-friendly table (1 row = 1 country-month record; 490 rows). Use this for pivot tables, charts, or AI analysis.
A9: • Monthly Detail — human-readable wide layout with monthly Cases/Qty pairs and formula-based annual totals. Includes source subtotal rows (grey).
A10: • Annual Summary — country x year cross-tables (SUMIFS on Monthly Detail) for each product/trade block.
A12: PRODUCTS COVERED
A13: • Dried deer velvet (녹용) — almost entirely IMPORT (China, Russia, New Zealand).
A14: • Frozen deer velvet (생녹용) — almost entirely IMPORT (New Zealand).
A15: • Deer velvet extract (녹용추출물) — mostly EXPORT (mainly USA, some Australia); one import record (NZ 2025). 2019–2025 only.
... A39: Dried deer velvet = 녹용 · Frozen deer velvet = 생녹용 · Deer velvet extract = 녹용추출물 · Cases = 건수 · Qty(kg) = 수량/중량 · QIA = 농림축산검역본부

Sheet Flat Data
A1: Year | B1: Month | C1: Trade | D1: Product | E1: Product_KR | F1: Country | G1: Cases | H1: Quantity_kg
A2: 2019 | B2: 1 | C2: Import | D2: Dried deer velvet | E2: 녹용 | F2: China | G2: 11 | H2: 6509.6 | J2: This sheet is the machine-friendly version: one row = one country-month record.
A3: 2019 | B3: 1 | C3: Import | D3: Dried deer velvet | E3: 녹용 | F3: Hong Kong | G3: 1 | H3: 353 | J3: No merged cells, no subtotal rows. Rows exist only where shipments occurred.
A4: 2019 | B4: 1 | C4: Import | D4: Dried deer velvet | E4: 녹용 | F4: New Zealand | G4: 3 | H4: 2819.49 | J4: 2026 covers Jan-Jun only, and includes Dried/Frozen velvet only (no extract queried).
A5: 2019 | B5: 1 | C5: Import | D5: Dried deer velvet | E5: 녹용 | F5: Russia | G5: 2 | H5: 1338 | J5: Use this sheet for pivot tables, charts, or AI analysis.
A6: 2019 | B6: 1 | C6: Import | D6: Frozen deer velvet | E6: 생녹용 | F6: New Zealand | G6: 2 | H6: 7649.46
A7: 2019 | B7: 2 | C7: Import | D7: Dried deer velvet | E7: 녹용 | F7: China | G7: 2 | H7: 4150
A8: 2019 | B8: 2 | C8: Import | D8: Dried deer velvet | E8: 녹용 | F8: Hong Kong | G8: 5 | H8: 3528.6
A9: 2019 | B9: 2 | C9: Import | D9: Dried deer velvet | E9: 녹용 | F9: New Zealand | G9: 3 | H9: 4578
A10: 2019 | B10: 2 | C10: Import | D10: Frozen deer velvet | E10: 생녹용 | F10: New Zealand | G10: 3 | H10: 14807.02
A11: 2019 | B11: 3 | C11: Export | D11: Deer velvet extract | E11: 녹용추출물 | F11: USA | G11: 2 | H11: 3141.8
A12: 2019 | B12: 3 | C12: Import | D12: Dried deer velvet | E12: 녹용 | F12: China | G12: 7 | H12: 7550.34
A13: 2019 | B13: 3 | C13: Import | D13: Dried deer velvet | E13: 녹용 | F13: Hong Kong | G13: 1 | H13: 400
A14: 2019 | B14: 3 | C14: Import | D14: Dried deer velvet | E14: 녹용 | F14: New Zealand | G14: 5 | H14: 6774.43
A15: 2019 | B15: 3 | C15: Import | D15: Frozen deer velvet | E15: 생녹용 | F15: New Zealand | G15: 6 | H15: 24581.28
A16: 2019 | B16: 4 | C16: Export | D16: Deer velvet extract | E16: 녹용추출물 | F16: USA | G16: 1 | H16: 3286
A17: 2019 | B17: 4 | C17: Import | D17: Dried deer velvet | E17: 녹용 | F17: China | G17: 5 | H17: 3178.3
... A491: 2026 | B491: 6 | C491: Import | D491: Frozen deer velvet | E491: 생녹용 | F491: New Zealand | G491: 1 | H491: 3051

Sheet Monthly Detail
A1: Year | B1: Trade | C1: Product | D1: Country | E1: Jan | G1: Feb | I1: Mar | K1: Apr | M1: May | O1: Jun | Q1: Jul | S1: Aug | U1: Sep | W1: Oct | Y1: Nov | AA1: Dec | AC1: Annual Cases | AD1: Annual Qty (kg)
E2: Cases | F2: Qty (kg) | G2: Cases | H2: Qty (kg) | I2: Cases | J2: Qty (kg) | K2: Cases | L2: Qty (kg) | M2: Cases | N2: Qty (kg) | O2: Cases | P2: Qty (kg) | Q2: Cases | R2: Qty (kg) | S2: Cases | T2: Qty (kg) | U2: Cases | V2: Qty (kg) | W2: Cases | X2: Qty (kg) | Y2: Cases | Z2: Qty (kg) | AA2: Cases | AB2: Qty (kg)
A3: 2019 | B3: Export | C3: Deer velvet extract | D3: USA | I3: 2 | J3: 3141.8 | K3: 1 | L3: 3286 | M3: 1 | N3: 3348 | O3: 1 | P3: 3472 | Q3: 1 | R3: 3720 | AA3: 2 | AB3: 3410 | AC3: =SUM(E3,G3,I3,K3,M3,O3,Q3,S3,U3,W3,Y3,AA3) -> 8 | AD3: =SUM(F3,H3,J3,L3,N3,P3,R3,T3,V3,X3,Z3,AB3) -> 20377.8
A4: 2019 | B4: Import | C4: Dried deer velvet | D4: China | E4: 11 | F4: 6509.6 | G4: 2 | H4: 4150 | I4: 7 | J4: 7550.34 | K4: 5 | L4: 3178.3 | M4: 12 | N4: 13226 | O4: 3 | P4: 1860 | Q4: 9 | R4: 13463.1 | S4: 3 | T4: 2680 | U4: 6 | V4: 4573.57 | W4: 6 | X4: 4956 | Y4: 5 | Z4: 2826.6 | AA4: 1 | AB4: 700 | AC4: =SUM(E4,G4,I4,K4,M4,O4,Q4,S4,U4,W4,Y4,AA4) -> 70 | AD4: =SUM(F4,H4,J4,L4,N4,P4,R4,T4,V4,X4,Z4,AB4) -> 65673.51
A5: 2019 | B5: Import | C5: Dried deer velvet | D5: Hong Kong | E5: 1 | F5: 353 | G5: 5 | H5: 3528.6 | I5: 1 | J5: 400 | K5: 4 | L5: 2026 | M5: 2 | N5: 1074.4 | O5: 1 | P5: 300 | Q5: 2 | R5: 2862 | S5: 2 | T5: 1030 | U5: 1 | V5: 621 | W5: 2 | X5: 1405 | Y5: 3 | Z5: 3826 | AA5: 1 | AB5: 400 | AC5: =SUM(E5,G5,I5,K5,M5,O5,Q5,S5,U5,W5,Y5,AA5) -> 25 | AD5: =SUM(F5,H5,J5,L5,N5,P5,R5,T5,V5,X5,Z5,AB5) -> 17826
A6: 2019 | B6: Import | C6: Dried deer velvet | D6: Kazakhstan | W6: 1 | X6: 140 | Y6: 2 | Z6: 396 | AA6: 1 | AB6: 165 | AC6: =SUM(E6,G6,I6,K6,M6,O6,Q6,S6,U6,W6,Y6,AA6) -> 4 | AD6: =SUM(F6,H6,J6,L6,N6,P6,R6,T6,V6,X6,Z6,AB6) -> 701
A7: 2019 | B7: Import | C7: Dried deer velvet | D7: New Zealand | E7: 3 | F7: 2819.49 | G7: 3 | H7: 4578 | I7: 5 | J7: 6774.43 | K7: 5 | L7: 5595.34 | M7: 3 | N7: 3111.18 | O7: 3 | P7: 2560.46 | Q7: 1 | R7: 1433.5 | S7: 3 | T7: 3537.51 | U7: 2 | V7: 5155.03 | W7: 1 | X7: 1155.6 | Y7: 2 | Z7: 1300 | AA7: 3 | AB7: 6000 | AC7: =SUM(E7,G7,I7,K7,M7,O7,Q7,S7,U7,W7,Y7,AA7) -> 34 | AD7: =SUM(F7,H7,J7,L7,N7,P7,R7,T7,V7,X7,Z7,AB7) -> 44020.54
A8: 2019 | B8: Import | C8: Dried deer velvet | D8: Russia | E8: 2 | F8: 1338 | K8: 2 | L8: 3017.16 | O8: 5 | P8: 3278.75 | Q8: 1 | R8: 441 | S8: 2 | T8: 520 | U8: 1 | V8: 234 | W8: 18 | X8: 17911.41 | Y8: 7 | Z8: 9844.03 | AA8: 10 | AB8: 9851.65 | AC8: =SUM(E8,G8,I8,K8,M8,O8,Q8,S8,U8,W8,Y8,AA8) -> 48 | AD8: =SUM(F8,H8,J8,L8,N8,P8,R8,T8,V8,X8,Z8,AB8) -> 46436
A9: 2019 | B9: Import | C9: Dried deer velvet | D9: Singapore | O9: 1 | P9: 500 | AC9: =SUM(E9,G9,I9,K9,M9,O9,Q9,S9,U9,W9,Y9,AA9) -> 1 | AD9: =SUM(F9,H9,J9,L9,N9,P9,R9,T9,V9,X9,Z9,AB9) -> 500
A10: 2019 | B10: Import | C10: Dried deer velvet | D10: Subtotal (source) | E10: 17 | F10: 11020.09 | G10: 10 | H10: 12256.6 | I10: 13 | J10: 14724.77 | K10: 16 | L10: 13816.8 | M10: 17 | N10: 17411.58 | O10: 13 | P10: 8499.21 | Q10: 13 | R10: 18199.6 | S10: 10 | T10: 7767.51 | U10: 10 | V10: 10583.6 | W10: 28 | X10: 25568.01 | Y10: 19 | Z10: 18192.63 | AA10: 16 | AB10: 17116.65 | AC10: =SUM(E10,G10,I10,K10,M10,O10,Q10,S10,U10,W10,Y10,AA10) -> 182 | AD10: =SUM(F10,H10,J10,L10,N10,P10,R10,T10,V10,X10,Z10,AB10) -> 175157.05
A11: 2019 | B11: Import | C11: Frozen deer velvet | D11: New Zealand | E11: 2 | F11: 7649.46 | G11: 3 | H11: 14807.02 | I11: 6 | J11: 24581.28 | K11: 2 | L11: 4985.86 | M11: 1 | N11: 767.75 | O11: 1 | P11: 1200 | Q11: 2 | R11: 9500 | S11: 2 | T11: 11990 | W11: 1 | X11: 1000 | Y11: 3 | Z11: 7300 | AA11: 5 | AB11: 15331.6 | AC11: =SUM(E11,G11,I11,K11,M11,O11,Q11,S11,U11,W11,Y11,AA11) -> 28 | AD11: =SUM(F11,H11,J11,L11,N11,P11,R11,T11,V11,X11,Z11,AB11) -> 99112.97
A12: 2019 | B12: Import | C12: Frozen deer velvet | D12: Subtotal (source) | E12: 2 | F12: 7649.46 | G12: 3 | H12: 14807.02 | I12: 6 | J12: 24581.28 | K12: 2 | L12: 4985.86 | M12: 1 | N12: 767.75 | O12: 1 | P12: 1200 | Q12: 2 | R12: 9500 | S12: 2 | T12: 11990 | W12: 1 | X12: 1000 | Y12: 3 | Z12: 7300 | AA12: 5 | AB12: 15331.6 | AC12: =SUM(E12,G12,I12,K12,M12,O12,Q12,S12,U12,W12,Y12,AA12) -> 28 | AD12: =SUM(F12,H12,J12,L12,N12,P12,R12,T12,V12,X12,Z12,AB12) -> 99112.97
A13: 2020 | B13: Export | C13: Dried deer velvet | D13: Hong Kong | Y13: 1 | Z13: 1540.4 | AC13: =SUM(E13,G13,I13,K13,M13,O13,Q13,S13,U13,W13,Y13,AA13) -> 1 | AD13: =SUM(F13,H13,J13,L13,N13,P13,R13,T13,V13,X13,Z13,AB13) -> 1540.4
A14: 2020 | B14: Export | C14: Dried deer velvet | D14: Subtotal (ea, source) | AC14: =SUM(E14,G14,I14,K14,M14,O14,Q14,S14,U14,W14,Y14,AA14) -> 0 | AD14: =SUM(F14,H14,J14,L14,N14,P14,R14,T14,V14,X14,Z14,AB14) -> 0
A15: 2020 | B15: Export | C15: Dried deer velvet | D15: Subtotal (kg, source) | Y15: 1 | Z15: 1540.4 | AC15: =SUM(E15,G15,I15,K15,M15,O15,Q15,S15,U15,W15,Y15,AA15) -> 1 | AD15: =SUM(F15,H15,J15,L15,N15,P15,R15,T15,V15,X15,Z15,AB15) -> 1540.4
A16: 2020 | B16: Export | C16: Deer velvet extract | D16: USA | G16: 1 | H16: 3098.4 | I16: 1 | J16: 1478.8 | K16: 1 | L16: 3410 | M16: 1 | N16: 247.5 | O16: 1 | P16: 247.5 | Q16: 1 | R16: 4092 | U16: 1 | V16: 4774 | W16: 1 | X16: 425.25 | Y16: 2 | Z16: 11321 | AA16: 1 | AB16: 94.5 | AC16: =SUM(E16,G16,I16,K16,M16,O16,Q16,S16,U16,W16,Y16,AA16) -> 11 | AD16: =SUM(F16,H16,J16,L16,N16,P16,R16,T16,V16,X16,Z16,AB16) -> 29188.95
A17: 2020 | B17: Import | C17: Dried deer velvet | D17: China | E17: 8 | F17: 7620 | G17: 6 | H17: 3823 | I17: 5 | J17: 3970 | K17: 7 | L17: 7688 | M17: 5 | N17: 3829 | O17: 10 | P17: 8451.62 | Q17: 7 | R17: 6165 | S17: 9 | T17: 5536.7 | U17: 5 | V17: 5250 | W17: 12 | X17: 7279 | Y17: 6 | Z17: 6025 | AA17: 9 | AB17: 12017.99 | AC17: =SUM(E17,G17,I17,K17,M17,O17,Q17,S17,U17,W17,Y17,AA17) -> 89 | AD17: =SUM(F17,H17,J17,L17,N17,P17,R17,T17,V17,X17,Z17,AB17) -> 77655.31
A18: 2020 | B18: Import | C18: Dried deer velvet | D18: Hong Kong | E18: 3 | F18: 2996.2 | G18: 1 | H18: 400 | I18: 2 | J18: 860 | K18: 2 | L18: 2085 | M18: 1 | N18: 360 | Q18: 1 | R18: 410 | S18: 1 | T18: 400 | U18: 2 | V18: 689.5 | W18: 1 | X18: 1340 | Y18: 2 | Z18: 750 | AA18: 2 | AB18: 3410 | AC18: =SUM(E18,G18,I18,K18,M18,O18,Q18,S18,U18,W18,Y18,AA18) -> 18 | AD18: =SUM(F18,H18,J18,L18,N18,P18,R18,T18,V18,X18,Z18,AB18) -> 13700.7
A19: 2020 | B19: Import | C19: Dried deer velvet | D19: Kazakhstan | E19: 1 | F19: 667 | U19: 2 | V19: 732.7 | W19: 2 | X19: 762.75 | AA19: 1 | AB19: 191 | AC19: =SUM(E19,G19,I19,K19,M19,O19,Q19,S19,U19,W19,Y19,AA19) -> 6 | AD19: =SUM(F19,H19,J19,L19,N19,P19,R19,T19,V19,X19,Z19,AB19) -> 2353.45
A20: 2020 | B20: Import | C20: Dried deer velvet | D20: New Zealand | E20: 2 | F20: 290.1 | G20: 5 | H20: 6919.98 | I20: 2 | J20: 2720 | M20: 5 | N20: 7824.41 | O20: 5 | P20: 5844.956 | Q20: 3 | R20: 4256.85 | S20: 4 | T20: 3988.41 | Y20: 4 | Z20: 3750.7 | AA20: 2 | AB20: 2030.54 | AC20: =SUM(E20,G20,I20,K20,M20,O20,Q20,S20,U20,W20,Y20,AA20) -> 32 | AD20: =SUM(F20,H20,J20,L20,N20,P20,R20,T20,V20,X20,Z20,AB20) -> 37625.946
A21: 2020 | B21: Import | C21: Dried deer velvet | D21: Russia | E21: 2 | F21: 2262.8 | G21: 1 | H21: 608.1 | I21: 1 | J21: 336 | M21: 3 | N21: 1775.71 | O21: 2 | P21: 2114.3 | Q21: 3 | R21: 1158 | S21: 1 | T21: 300.1 | U21: 3 | V21: 1693.9 | W21: 17 | X21: 18701.98 | Y21: 14 | Z21: 16630.86 | AA21: 11 | AB21: 8459.7 | AC21: =SUM(E21,G21,I21,K21,M21,O21,Q21,S21,U21,W21,Y21,AA21) -> 58 | AD21: =SUM(F21,H21,J21,L21,N21,P21,R21,T21,V21,X21,Z21,AB21) -> 54041.45
A22: 2020 | B22: Import | C22: Dried deer velvet | D22: Subtotal (source) | E22: 16 | F22: 13836.1 | G22: 13 | H22: 11751.08 | I22: 10 | J22: 7886 | K22: 9 | L22: 9773 | M22: 14 | N22: 13789.12 | O22: 17 | P22: 16410.876 | Q22: 14 | R22: 11989.85 | S22: 15 | T22: 10225.21 | U22: 12 | V22: 8366.1 | W22: 32 | X22: 28083.73 | Y22: 26 | Z22: 27156.56 | AA22: 25 | AB22: 26109.23 | AC22: =SUM(E22,G22,I22,K22,M22,O22,Q22,S22,U22,W22,Y22,AA22) -> 203 | AD22: =SUM(F22,H22,J22,L22,N22,P22,R22,T22,V22,X22,Z22,AB22) -> 185376.86
A23: 2020 | B23: Import | C23: Frozen deer velvet | D23: New Zealand | E23: 3 | F23: 6630 | G23: 5 | H23: 15200 | I23: 2 | J23: 9223 | K23: 2 | L23: 12086.05 | M23: 1 | N23: 3610 | O23: 2 | P23: 6321.5 | Q23: 3 | R23: 8906.82 | S23: 1 | T23: 4000 | AA23: 3 | AB23: 11500 | AC23: =SUM(E23,G23,I23,K23,M23,O23,Q23,S23,U23,W23,Y23,AA23) -> 22 | AD23: =SUM(F23,H23,J23,L23,N23,P23,R23,T23,V23,X23,Z23,AB23) -> 77477.37
A24: 2020 | B24: Import | C24: Frozen deer velvet | D24: Subtotal (source) | E24: 3 | F24: 6630 | G24: 5 | H24: 15200 | I24: 2 | J24: 9223 | K24: 2 | L24: 12086.05 | M24: 1 | N24: 3610 | O24: 2 | P24: 6321.5 | Q24: 3 | R24: 8906.82 | S24: 1 | T24: 4000 | AA24: 3 | AB24: 11500 | AC24: =SUM(E24,G24,I24,K24,M24,O24,Q24,S24,U24,W24,Y24,AA24) -> 22 | AD24: =SUM(F24,H24,J24,L24,N24,P24,R24,T24,V24,X24,Z24,AB24) -> 77477.37
A25: 2021 | B25: Export | C25: Dried deer velvet | D25: China | U25: 1 | V25: 10 | AC25: =SUM(E25,G25,I25,K25,M25,O25,Q25,S25,U25,W25,Y25,AA25) -> 1 | AD25: =SUM(F25,H25,J25,L25,N25,P25,R25,T25,V25,X25,Z25,AB25) -> 10
A26: 2021 | B26: Export | C26: Dried deer velvet | D26: Hong Kong | W26: 1 | X26: 1772.06 | Y26: 1 | Z26: 2003.64 | AC26: =SUM(E26,G26,I26,K26,M26,O26,Q26,S26,U26,W26,Y26,AA26) -> 2 | AD26: =SUM(F26,H26,J26,L26,N26,P26,R26,T26,V26,X26,Z26,AB26) -> 3775.7
A27: 2021 | B27: Export | C27: Deer velvet extract | D27: Australia | I27: 1 | J27: 576 | M27: 1 | N27: 682 | Q27: 1 | R27: 180 | S27: 1 | T27: 192 | U27: 1 | V27: 180 | AC27: =SUM(E27,G27,I27,K27,M27,O27,Q27,S27,U27,W27,Y27,AA27) -> 5 | AD27: =SUM(F27,H27,J27,L27,N27,P27,R27,T27,V27,X27,Z27,AB27) -> 1810
A28: 2021 | B28: Export | C28: Deer velvet extract | D28: USA | K28: 2 | L28: 702.75 | M28: 2 | N28: 4638.5 | O28: 2 | P28: 120 | S28: 1 | T28: 3410 | U28: 2 | V28: 1281 | W28: 5 | X28: 13383.25 | Y28: 1 | Z28: 36 | AA28: 1 | AB28: 270 | AC28: =SUM(E28,G28,I28,K28,M28,O28,Q28,S28,U28,W28,Y28,AA28) -> 16 | AD28: =SUM(F28,H28,J28,L28,N28,P28,R28,T28,V28,X28,Z28,AB28) -> 23841.5
A29: 2021 | B29: Import | C29: Dried deer velvet | D29: China | E29: 12 | F29: 7215 | G29: 4 | H29: 2346.36 | I29: 9 | J29: 7977 | K29: 4 | L29: 5300 | M29: 9 | N29: 8900 | Q29: 3 | R29: 2050 | S29: 6 | T29: 10141.9 | U29: 5 | V29: 6330 | W29: 6 | X29: 5008.89 | Y29: 6 | Z29: 8377.425 | AA29: 8 | AB29: 8839.25 | AC29: =SUM(E29,G29,I29,K29,M29,O29,Q29,S29,U29,W29,Y29,AA29) -> 72 | AD29: =SUM(F29,H29,J29,L29,N29,P29,R29,T29,V29,X29,Z29,AB29) -> 72485.825
A30: 2021 | B30: Import | C30: Dried deer velvet | D30: Hong Kong | G30: 1 | H30: 400 | I30: 1 | J30: 2800 | K30: 1 | L30: 400 | M30: 2 | N30: 1785.8 | O30: 1 | P30: 400 | S30: 2 | T30: 800 | U30: 2 | V30: 2350 | W30: 3 | X30: 9097 | Y30: 3 | Z30: 1638.875 | AA30: 3 | AB30: 2700 | AC30: =SUM(E30,G30,I30,K30,M30,O30,Q30,S30,U30,W30,Y30,AA30) -> 19 | AD30: =SUM(F30,H30,J30,L30,N30,P30,R30,T30,V30,X30,Z30,AB30) -> 22371.675
A31: 2021 | B31: Import | C31: Dried deer velvet | D31: Kazakhstan | U31: 3 | V31: 1288 | W31: 1 | X31: 140 | AC31: =SUM(E31,G31,I31,K31,M31,O31,Q31,S31,U31,W31,Y31,AA31) -> 4 | AD31: =SUM(F31,H31,J31,L31,N31,P31,R31,T31,V31,X31,Z31,AB31) -> 1428
A32: 2021 | B32: Import | C32: Dried deer velvet | D32: New Zealand | E32: 4 | F32: 1910.17 | G32: 1 | H32: 1278.38 | I32: 5 | J32: 4667.63 | K32: 2 | L32: 2408.74 | M32: 4 | N32: 4557.59 | O32: 3 | P32: 3735.66 | Q32: 2 | R32: 1938.22 | S32: 2 | T32: 3466.04 | W32: 1 | X32: 1.5 | Y32: 2 | Z32: 160 | AC32: =SUM(E32,G32,I32,K32,M32,O32,Q32,S32,U32,W32,Y32,AA32) -> 26 | AD32: =SUM(F32,H32,J32,L32,N32,P32,R32,T32,V32,X32,Z32,AB32) -> 24123.93
A33: 2021 | B33: Import | C33: Dried deer velvet | D33: Russia | E33: 1 | F33: 479 | G33: 2 | H33: 2179.75 | I33: 1 | J33: 981 | K33: 1 | L33: 313 | M33: 2 | N33: 1068 | Q33: 1 | R33: 111.25 | S33: 1 | T33: 711.75 | U33: 3 | V33: 1829 | W33: 14 | X33: 24864.6 | Y33: 13 | Z33: 17976.79 | AA33: 5 | AB33: 5466.05 | AC33: =SUM(E33,G33,I33,K33,M33,O33,Q33,S33,U33,W33,Y33,AA33) -> 44 | AD33: =SUM(F33,H33,J33,L33,N33,P33,R33,T33,V33,X33,Z33,AB33) -> 55980.19
A34: 2021 | B34: Import | C34: Frozen deer velvet | D34: New Zealand | E34: 5 | F34: 23775 | G34: 2 | H34: 6300 | K34: 4 | L34: 15700 | M34: 2 | N34: 5500 | O34: 2 | P34: 7222.14 | Q34: 2 | R34: 5500 | W34: 2 | X34: 7377 | Y34: 2 | Z34: 4500 | AA34: 4 | AB34: 16000 | AC34: =SUM(E34,G34,I34,K34,M34,O34,Q34,S34,U34,W34,Y34,AA34) -> 25 | AD34: =SUM(F34,H34,J34,L34,N34,P34,R34,T34,V34,X34,Z34,AB34) -> 91874.14
A35: 2022 | B35: Export | C35: Dried deer velvet | D35: Vietnam | K35: 1 | L35: 220 | AC35: =SUM(E35,G35,I35,K35,M35,O35,Q35,S35,U35,W35,Y35,AA35) -> 1 | AD35: =SUM(F35,H35,J35,L35,N35,P35,R35,T35,V35,X35,Z35,AB35) -> 220
A36: 2022 | B36: Export | C36: Dried deer velvet | D36: Subtotal (ea, source) | AC36: =SUM(E36,G36,I36,K36,M36,O36,Q36,S36,U36,W36,Y36,AA36) -> 0 | AD36: =SUM(F36,H36,J36,L36,N36,P36,R36,T36,V36,X36,Z36,AB36) -> 0
A37: 2022 | B37: Export | C37: Dried deer velvet | D37: Subtotal (kg, source) | K37: 1 | L37: 220 | AC37: =SUM(E37,G37,I37,K37,M37,O37,Q37,S37,U37,W37,Y37,AA37) -> 1 | AD37: =SUM(F37,H37,J37,L37,N37,P37,R37,T37,V37,X37,Z37,AB37) -> 220
A38: 2022 | B38: Export | C38: Deer velvet extract | D38: Australia | E38: 1 | F38: 460 | Q38: 1 | R38: 276 | AC38: =SUM(E38,G38,I38,K38,M38,O38,Q38,S38,U38,W38,Y38,AA38) -> 2 | AD38: =SUM(F38,H38,J38,L38,N38,P38,R38,T38,V38,X38,Z38,AB38) -> 736
A39: 2022 | B39: Export | C39: Deer velvet extract | D39: USA | E39: 2 | F39: 829 | G39: 3 | H39: 2341.4 | I39: 2 | J39: 6941.8 | K39: 2 | L39: 3412.8 | M39: 3 | N39: 6597.375 | O39: 1 | P39: 2.25 | Q39: 2 | R39: 1226.25 | S39: 4 | T39: 15550.5 | U39: 3 | V39: 1699.5 | AA39: 2 | AB39: 6272.3 | AC39: =SUM(E39,G39,I39,K39,M39,O39,Q39,S39,U39,W39,Y39,AA39) -> 24 | AD39: =SUM(F39,H39,J39,L39,N39,P39,R39,T39,V39,X39,Z39,AB39) -> 44873.175
A40: 2022 | B40: Import | C40: Dried deer velvet | D40: China | E40: 4 | F40: 5600 | G40: 4 | H40: 4548.6 | I40: 2 | J40: 1080.258 | K40: 6 | L40: 9020 | M40: 7 | N40: 6053.175 | O40: 6 | P40: 3210 | Q40: 7 | R40: 13500 | S40: 6 | T40: 6096 | U40: 3 | V40: 4780 | W40: 7 | X40: 14334.3 | Y40: 6 | Z40: 11862.5 | AA40: 9 | AB40: 9467 | AC40: =SUM(E40,G40,I40,K40,M40,O40,Q40,S40,U40,W40,Y40,AA40) -> 67 | AD40: =SUM(F40,H40,J40,L40,N40,P40,R40,T40,V40,X40,Z40,AB40) -> 89551.833
...

Sheet Annual Summary
A1: Import — Dried deer velvet: Annual Quarantine Results by Country
A2: Country | B2: 2019 Cases | C2: 2019 Qty (kg) | D2: 2020 Cases | E2: 2020 Qty (kg) | F2: 2021 Cases | G2: 2021 Qty (kg) | H2: 2022 Cases | I2: 2022 Qty (kg) | J2: 2023 Cases | K2: 2023 Qty (kg) | L2: 2024 Cases | M2: 2024 Qty (kg) | N2: 2025 Cases | O2: 2025 Qty (kg) | P2: 2026* Cases | Q2: 2026* Qty (kg)
A3: Australia | B3: =SUMIFS('Monthly Detail'!$AC$3:$AC$92,'Monthly Detail'!$A$3:$A$92,2019,'Monthly Detail'!$B$3:$B$92,"Import",'Monthly Detail'!$C$3:$C$92,"Dried deer velvet",'Monthly Detail'!$D$3:$D$92,$A3) -> 0 | C3: =SUMIFS('Monthly Detail'!$AD$3:$AD$92,'Monthly Detail'!$A$3:$A$92,2019,'Monthly Detail'!$B$3:$B$92,"Import",'Monthly Detail'!$C$3:$C$92,"Dried deer velvet",'Monthly Detail'!$D$3:$D$92,$A3) -> 0 | D3: =SUMIFS('Monthly Detail'!$AC$3:$AC$92,'Monthly Detail'!$A$3:$A$92,2020,'Monthly Detail'!$B$3:$B$92,"Import",'Monthly Detail'!$C$3:$C$92,"Dried deer velvet",'Monthly Detail'!$D$3:$D$92,$A3) -> 0 | E3: =SUMIFS('Monthly Detail'!$AD$3:$AD$92,'Monthly Detail'!$A$3:$A$92,2020,'Monthly Detail'!$B$3:$B$92,"Import",'Monthly Detail'!$C$3:$C$92,"Dried deer velvet",'Monthly Detail'!$D$3:$D$92,$A3) -> 0 | F3: =SUMIFS('Monthly Detail'!$AC$3:$AC$92,'Monthly Detail'!$A$3:$A$92,2021,'Monthly Detail'!$B$3:$B$92,"Import",'Monthly Detail'!$C$3:$C$92,"Dried deer velvet",'Monthly Detail'!$D$3:$D$92,$A3) -> 0 | G3: =SUMIFS('Monthly Detail'!$AD$3:$AD$92,'Monthly Detail'!$A$3:$A$92,2021,'Monthly Detail'!$B$3:$B$92,"Import",'Monthly Detail'!$C$3:$C$92,"Dried deer velvet",'Monthly Detail'!$D$3:$D$92,$A3) -> 0 | H3: =SUMIFS('Monthly Detail'!$AC$3:$AC$92,'Monthly Detail'!$A$3:$A$92,2022,'Monthly Detail'!$B$3:$B$92,"Import",'Monthly Detail'!$C$3:$C$92,"Dried deer velvet",'Monthly Detail'!$D$3:$D$92,$A3) -> 0 | I3: =SUMIFS('Monthly Detail'!$AD$3:$AD$92,'Monthly Detail'!$A$3:$A$92,2022,'Monthly Detail'!$B$3:$B$92,"Import",'Monthly Detail'!$C$3:$C$92,"Dried deer velvet",'Monthly Detail'!$D$3:$D$92,$A3) -> 0 | J3: =SUMIFS('Monthly Detail'!$AC$3:$AC$92,'Monthly Detail'!$A$3:$A$92,2023,'Monthly Detail'!$B$3:$B$92,"Import",'Monthly Detail'!$C$3:$C$92,"Dried deer velvet",'Monthly Detail'!$D$3:$D$92,$A3) -> 0 | K3: =SUMIFS('Monthly Detail'!$AD$3:$AD$92,'Monthly Detail'!$A$3:$A$92,2023,'Monthly Detail'!$B$3:$B$92,"Import",'Monthly Detail'!$C$3:$C$92,"Dried deer velvet",'Monthly Detail'!$D$3:$D$92,$A3) -> 0 | L3: =SUMIFS('Monthly Detail'!$AC$3:$AC$92,'Monthly Detail'!$A$3:$A$92,2024,'Monthly Detail'!$B$3:$B$92,"Import",'Monthly Detail'!$C$3:$C$92,"Dried deer velvet",'Monthly Detail'!$D$3:$D$92,$A3) -> 0 | M3: =SUMIFS('Monthly Detail'!$AD$3:$AD$92,'Monthly Detail'!$A$3:$A$92,2024,'Monthly Detail'!$B$3:$B$92,"Import",'Monthly Detail'!$C$3:$C$92,"Dried deer velvet",'Monthly Detail'!$D$3:$D$92,$A3) -> 0 | N3: =SUMIFS('Monthly Detail'!$AC$3:$AC$92,'Monthly Detail'!$A$3:$A$92,2025,'Monthly Detail'!$B$3:$B$92,"Import",'Monthly Detail'!$C$3:$C$92,"Dried deer velvet",'Monthly Detail'!$D$3:$D$92,$A3) -> 0 | O3: =SUMIFS('Monthly Detail'!$AD$3:$AD$92,'Monthly Detail'!$A$3:$A$92,2025,'Monthly Detail'!$B$3:$B$92,"Import",'Monthly Detail'!$C$3:$C$92,"Dried deer velvet",'Monthly Detail'!$D$3:$D$92,$A3) -> 0 | P3: =SUMIFS('Monthly Detail'!$AC$3:$AC$92,'Monthly Detail'!$A$3:$A$92,2026,'Monthly Detail'!$B$3:$B$92,"Import",'Monthly Detail'!$C$3:$C$92,"Dried deer velvet",'Monthly Detail'!$D$3:$D$92,$A3) -> 13 | Q3: =SUMIFS('Monthly Detail'!$AD$3:$AD$92,'Monthly Detail'!$A$3:$A$92,2026,'Monthly Detail'!$B$3:$B$92,"Import",'Monthly Detail'!$C$3:$C$92,"Dried deer velvet",'Monthly Detail'!$D$3:$D$92,$A3) -> 1.8
A4: Canada | B4: =SUMIFS('Monthly Detail'!$AC$3:$AC$92,'Monthly Detail'!$A$3:$A$92,2019,'Monthly Detail'!$B$3:$B$92,"Import",'Monthly Detail'!$C$3:$C$92,"Dried deer velvet",'Monthly Detail'!$D$3:$D$92,$A4) -> 0 | C4: =SUMIFS('Monthly Detail'!$AD$3:$AD$92,'Monthly Detail'!$A$3:$A$92,2019,'Monthly Detail'!$B$3:$B$92,"Import",'Monthly Detail'!$C$3:$C$92,"Dried deer velvet",'Monthly Detail'!$D$3:$D$92,$A4) -> 0 | D4: =SUMIFS('Monthly Detail'!$AC$3:$AC$92,'Monthly Detail'!$A$3:$A$92,2020,'Monthly Detail'!$B$3:$B$92,"Import",'Monthly Detail'!$C$3:$C$92,"Dried deer velvet",'Monthly Detail'!$D$3:$D$92,$A4) -> 0 | E4: =SUMIFS('Monthly Detail'!$AD$3:$AD$92,'Monthly Detail'!$A$3:$A$92,2020,'Monthly Detail'!$B$3:$B$92,"Import",'Monthly Detail'!$C$3:$C$92,"Dried deer velvet",'Monthly Detail'!$D$3:$D$92,$A4) -> 0 | F4: =SUMIFS('Monthly Detail'!$AC$3:$AC$92,'Monthly Detail'!$A$3:$A$92,2021,'Monthly Detail'!$B$3:$B$92,"Import",'Monthly Detail'!$C$3:$C$92,"Dried deer velvet",'Monthly Detail'!$D$3:$D$92,$A4) -> 0 | G4: =SUMIFS('Monthly Detail'!$AD$3:$AD$92,'Monthly Detail'!$A$3:$A$92,2021,'Monthly Detail'!$B$3:$B$92,"Import",'Monthly Detail'!$C$3:$C$92,"Dried deer velvet",'Monthly Detail'!$D$3:$D$92,$A4) -> 0 | H4: =SUMIFS('Monthly Detail'!$AC$3:$AC$92,'Monthly Detail'!$A$3:$A$92,2022,'Monthly Detail'!$B$3:$B$92,"Import",'Monthly Detail'!$C$3:$C$92,"Dried deer velvet",'Monthly Detail'!$D$3:$D$92,$A4) -> 0 | I4: =SUMIFS('Monthly Detail'!$AD$3:$AD$92,'Monthly Detail'!$A$3:$A$92,2022,'Monthly Detail'!$B$3:$B$92,"Import",'Monthly Detail'!$C$3:$C$92,"Dried deer velvet",'Monthly Detail'!$D$3:$D$92,$A4) -> 0 | J4: =SUMIFS('Monthly Detail'!$AC$3:$AC$92,'Monthly Detail'!$A$3:$A$92,2023,'Monthly Detail'!$B$3:$B$92,"Import",'Monthly Detail'!$C$3:$C$92,"Dried deer velvet",'Monthly Detail'!$D$3:$D$92,$A4) -> 0 | K4: =SUMIFS('Monthly Detail'!$AD$3:$AD$92,'Monthly Detail'!$A$3:$A$92,2023,'Monthly Detail'!$B$3:$B$92,"Import",'Monthly Detail'!$C$3:$C$92,"Dried deer velvet",'Monthly Detail'!$D$3:$D$92,$A4) -> 0 | L4: =SUMIFS('Monthly Detail'!$AC$3:$AC$92,'Monthly Detail'!$A$3:$A$92,2024,'Monthly Detail'!$B$3:$B$92,"Import",'Monthly Detail'!$C$3:$C$92,"Dried deer velvet",'Monthly Detail'!$D$3:$D$92,$A4) -> 0 | M4: =SUMIFS('Monthly Detail'!$AD$3:$AD$92,'Monthly Detail'!$A$3:$A$92,2024,'Monthly Detail'!$B$3:$B$92,"Import",'Monthly Detail'!$C$3:$C$92,"Dried deer velvet",'Monthly Detail'!$D$3:$D$92,$A4) -> 0 | N4: =SUMIFS('Monthly Detail'!$AC$3:$AC$92,'Monthly Detail'!$A$3:$A$92,2025,'Monthly Detail'!$B$3:$B$92,"Import",'Monthly Detail'!$C$3:$C$92,"Dried deer velvet",'Monthly Detail'!$D$3:$D$92,$A4) -> 0 | O4: =SUMIFS('Monthly Detail'!$AD$3:$AD$92,'Monthly Detail'!$A$3:$A$92,2025,'Monthly Detail'!$B$3:$B$92,"Import",'Monthly Detail'!$C$3:$C$92,"Dried deer velvet",'Monthly Detail'!$D$3:$D$92,$A4) -> 0 | P4: =SUMIFS('Monthly Detail'!$AC$3:$AC$92,'Monthly Detail'!$A$3:$A$92,2026,'Monthly Detail'!$B$3:$B$92,"Import",'Monthly Detail'!$C$3:$C$92,"Dried deer velvet",'Monthly Detail'!$D$3:$D$92,$A4) -> 1 | Q4: =SUMIFS('Monthly Detail'!$AD$3:$AD$92,'Monthly Detail'!$A$3:$A$92,2026,'Monthly Detail'!$B$3:$B$92,"Import",'Monthly Detail'!$C$3:$C$92,"Dried deer velvet",'Monthly Detail'!$D$3:$D$92,$A4) -> 0.1
A5: China | B5: =SUMIFS('Monthly Detail'!$AC$3:$AC$92,'Monthly Detail'!$A$3:$A$92,2019,'Monthly Detail'!$B$3:$B$92,"Import",'Monthly Detail'!$C$3:$C$92,"Dried deer velvet",'Monthly Detail'!$D$3:$D$92,$A5) -> 70 | C5: =SUMIFS('Monthly Detail'!$AD$3:$AD$92,'Monthly Detail'!$A$3:$A$92,2019,'Monthly Detail'!$B$3:$B$92,"Import",'Monthly Detail'!$C$3:$C$92,"Dried deer velvet",'Monthly Detail'!$D$3:$D$92,$A5) -> 65673.51 | D5: =SUMIFS('Monthly Detail'!$AC$3:$AC$92,'Monthly Detail'!$A$3:$A$92,2020,'Monthly Detail'!$B$3:$B$92,"Import",'Monthly Detail'!$C$3:$C$92,"Dried deer velvet",'Monthly Detail'!$D$3:$D$92,$A5) -> 89 | E5: =SUMIFS('Monthly Detail'!$AD$3:$AD$92,'Monthly Detail'!$A$3:$A$92,2020,'Monthly Detail'!$B$3:$B$92,"Import",'Monthly Detail'!$C$3:$C$92,"Dried deer velvet",'Monthly Detail'!$D$3:$D$92,$A5) -> 77655.31 | F5: =SUMIFS('Monthly Detail'!$AC$3:$AC$92,'Monthly Detail'!$A$3:$A$92,2021,'Monthly Detail'!$B$3:$B$92,"Import",'Monthly Detail'!$C$3:$C$92,"Dried deer velvet",'Monthly Detail'!$D$3:$D$92,$A5) -> 72 | G5: =SUMIFS('Monthly Detail'!$AD$3:$AD$92,'Monthly Detail'!$A$3:$A$92,2021,'Monthly Detail'!$B$3:$B$92,"Import",'Monthly Detail'!$C$3:$C$92,"Dried deer velvet",'Monthly Detail'!$D$3:$D$92,$A5) -> 72485.825 | H5: =SUMIFS('Monthly Detail'!$AC$3:$AC$92,'Monthly Detail'!$A$3:$A$92,2022,'Monthly Detail'!$B$3:$B$92,"Import",'Monthly Detail'!$C$3:$C$92,"Dried deer velvet",'Monthly Detail'!$D$3:$D$92,$A5) -> 67 | I5: =SUMIFS('Monthly Detail'!$AD$3:$AD$92,'Monthly Detail'!$A$3:$A$92,2022,'Monthly Detail'!$B$3:$B$92,"Import",'Monthly Detail'!$C$3:$C$92,"Dried deer velvet",'Monthly Detail'!$D$3:$D$92,$A5) -> 89551.833 | J5: =SUMIFS('Monthly Detail'!$AC$3:$AC$92,'Monthly Detail'!$A$3:$A$92,2023,'Monthly Detail'!$B$3:$B$92,"Import",'Monthly Detail'!$C$3:$C$92,"Dried deer velvet",'Monthly Detail'!$D$3:$D$92,$A5) -> 56 | K5: =SUMIFS('Monthly Detail'!$AD$3:$AD$92,'Monthly Detail'!$A$3:$A$92,2023,'Monthly Detail'!$B$3:$B$92,"Import",'Monthly Detail'!$C$3:$C$92,"Dried deer velvet",'Monthly Detail'!$D$3:$D$92,$A5) -> 74242.8 | L5: =SUMIFS('Monthly Detail'!$AC$3:$AC$92,'Monthly Detail'!$A$3:$A$92,2024,'Monthly Detail'!$B$3:$B$92,"Import",'Monthly Detail'!$C$3:$C$92,"Dried deer velvet",'Monthly Detail'!$D$3:$D$92,$A5) -> 64 | M5: =SUMIFS('Monthly Detail'!$AD$3:$AD$92,'Monthly Detail'!$A$3:$A$92,2024,'Monthly Detail'!$B$3:$B$92,"Import",'Monthly Detail'!$C$3:$C$92,"Dried deer velvet",'Monthly Detail'!$D$3:$D$92,$A5) -> 89389.825 | N5: =SUMIFS('Monthly Detail'!$AC$3:$AC$92,'Monthly Detail'!$A$3:$A$92,2025,'Monthly Detail'!$B$3:$B$92,"Import",'Monthly Detail'!$C$3:$C$92,"Dried deer velvet",'Monthly Detail'!$D$3:$D$92,$A5) -> 57 | O5: =SUMIFS('Monthly Detail'!$AD$3:$AD$92,'Monthly Detail'!$A$3:$A$92,2025,'Monthly Detail'!$B$3:$B$92,"Import",'Monthly Detail'!$C$3:$C$92,"Dried deer velvet",'Monthly Detail'!$D$3:$D$92,$A5) -> 90393 | P5: =SUMIFS('Monthly Detail'!$AC$3:$AC$92,'Monthly Detail'!$A$3:$A$92,2026,'Monthly Detail'!$B$3:$B$92,"Import",'Monthly Detail'!$C$3:$C$92,"Dried deer velvet",'Monthly Detail'!$D$3:$D$92,$A5) -> 33 | Q5: =SUMIFS('Monthly Detail'!$AD$3:$AD$92,'Monthly Detail'!$A$3:$A$92,2026,'Monthly Detail'!$B$3:$B$92,"Import",'Monthly Detail'!$C$3:$C$92,"Dried deer velvet",'Monthly Detail'!$D$3:$D$92,$A5) -> 36527.4
A6: Hong Kong | B6: =SUMIFS('Monthly Detail'!$AC$3:$AC$92,'Monthly Detail'!$A$3:$A$92,2019,'Monthly Detail'!$B$3:$B$92,"Import",'Monthly Detail'!$C$3:$C$92,"Dried deer velvet",'Monthly Detail'!$D$3:$D$92,$A6) -> 25 | C6: =SUMIFS('Monthly Detail'!$AD$3:$AD$92,'Monthly Detail'!$A$3:$A$92,2019,'Monthly Detail'!$B$3:$B$92,"Import",'Monthly Detail'!$C$3:$C$92,"Dried deer velvet",'Monthly Detail'!$D$3:$D$92,$A6) -> 17826 | D6: =SUMIFS('Monthly Detail'!$AC$3:$AC$92,'Monthly Detail'!$A$3:$A$92,2020,'Monthly Detail'!$B$3:$B$92,"Import",'Monthly Detail'!$C$3:$C$92,"Dried deer velvet",'Monthly Detail'!$D$3:$D$92,$A6) -> 18 | E6: =SUMIFS('Monthly Detail'!$AD$3:$AD$92,'Monthly Detail'!$A$3:$A$92,2020,'Monthly Detail'!$B$3:$B$92,"Import",'Monthly Detail'!$C$3:$C$92,"Dried deer velvet",'Monthly Detail'!$D$3:$D$92,$A6) -> 13700.7 | F6: =SUMIFS('Monthly Detail'!$AC$3:$AC$92,'Monthly Detail'!$A$3:$A$92,2021,'Monthly Detail'!$B$3:$B$92,"Import",'Monthly Detail'!$C$3:$C$92,"Dried deer velvet",'Monthly Detail'!$D$3:$D$92,$A6) -> 19 | G6: =SUMIFS('Monthly Detail'!$AD$3:$AD$92,'Monthly Detail'!$A$3:$A$92,2021,'Monthly Detail'!$B$3:$B$92,"Import",'Monthly Detail'!$C$3:$C$92,"Dried deer velvet",'Monthly Detail'!$D$3:$D$92,$A6) -> 22371.675 | H6: =SUMIFS('Monthly Detail'!$AC$3:$AC$92,'Monthly Detail'!$A$3:$A$92,2022,'Monthly Detail'!$B$3:$B$92,"Import",'Monthly Detail'!$C$3:$C$92,"Dried deer velvet",'Monthly Detail'!$D$3:$D$92,$A6) -> 18 | I6: =SUMIFS('Monthly Detail'!$AD$3:$AD$92,'Monthly Detail'!$A$3:$A$92,2022,'Monthly Detail'!$B$3:$B$92,"Import",'Monthly Detail'!$C$3:$C$92,"Dried deer velvet",'Monthly Detail'!$D$3:$D$92,$A6) -> 23834.6 | J6: =SUMIFS('Monthly Detail'!$AC$3:$AC$92,'Monthly Detail'!$A$3:$A$92,2023,'Monthly Detail'!$B$3:$B$92,"Import",'Monthly Detail'!$C$3:$C$92,"Dried deer velvet",'Monthly Detail'!$D$3:$D$92,$A6) -> 12 | K6: =SUMIFS('Monthly Detail'!$AD$3:$AD$92,'Monthly Detail'!$A$3:$A$92,2023,'Monthly Detail'!$B$3:$B$92,"Import",'Monthly Detail'!$C$3:$C$92,"Dried deer velvet",'Monthly Detail'!$D$3:$D$92,$A6) -> 12596 | L6: =SUMIFS('Monthly Detail'!$AC$3:$AC$92,'Monthly Detail'!$A$3:$A$92,2024,'Monthly Detail'!$B$3:$B$92,"Import",'Monthly Detail'!$C$3:$C$92,"Dried deer velvet",'Monthly Detail'!$D$3:$D$92,$A6) -> 3 | M6: =SUMIFS('Monthly Detail'!$AD$3:$AD$92,'Monthly Detail'!$A$3:$A$92,2024,'Monthly Detail'!$B$3:$B$92,"Import",'Monthly Detail'!$C$3:$C$92,"Dried deer velvet",'Monthly Detail'!$D$3:$D$92,$A6) -> 4346 | N6: =SUMIFS('Monthly Detail'!$AC$3:$AC$92,'Monthly Detail'!$A$3:$A$92,2025,'Monthly Detail'!$B$3:$B$92,"Import",'Monthly Detail'!$C$3:$C$92,"Dried deer velvet",'Monthly Detail'!$D$3:$D$92,$A6) -> 6 | O6: =SUMIFS('Monthly Detail'!$AD$3:$AD$92,'Monthly Detail'!$A$3:$A$92,2025,'Monthly Detail'!$B$3:$B$92,"Import",'Monthly Detail'!$C$3:$C$92,"Dried deer velvet",'Monthly Detail'!$D$3:$D$92,$A6) -> 3698.6 | P6: =SUMIFS('Monthly Detail'!$AC$3:$AC$92,'Monthly Detail'!$A$3:$A$92,2026,'Monthly Detail'!$B$3:$B$92,"Import",'Monthly Detail'!$C$3:$C$92,"Dried deer velvet",'Monthly Detail'!$D$3:$D$92,$A6) -> 4 | Q6: =SUMIFS('Monthly Detail'!$AD$3:$AD$92,'Monthly Detail'!$A$3:$A$92,2026,'Monthly Detail'!$B$3:$B$92,"Import",'Monthly Detail'!$C$3:$C$92,"Dried deer velvet",'Monthly Detail'!$D$3:$D$92,$A6) -> 1800
A7: Kazakhstan | B7: =SUMIFS('Monthly Detail'!$AC$3:$AC$92,'Monthly Detail'!$A$3:$A$92,2019,'Monthly Detail'!$B$3:$B$92,"Import",'Monthly Detail'!$C$3:$C$92,"Dried deer velvet",'Monthly Detail'!$D$3:$D$92,$A7) -> 4 | C7: =SUMIFS('Monthly Detail'!$AD$3:$AD$92,'Monthly Detail'!$A$3:$A$92,2019,'Monthly Detail'!$B$3:$B$92,"Import",'Monthly Detail'!$C$3:$C$92,"Dried deer velvet",'Monthly Detail'!$D$3:$D$92,$A7) -> 701 | D7: =SUMIFS('Monthly Detail'!$AC$3:$AC$92,'Monthly Detail'!$A$3:$A$92,2020,'Monthly Detail'!$B$3:$B$92,"Import",'Monthly Detail'!$C$3:$C$92,"Dried deer velvet",'Monthly Detail'!$D$3:$D$92,$A7) -> 6 | E7: =SUMIFS('Monthly Detail'!$AD$3:$AD$92,'Monthly Detail'!$A$3:$A$92,2020,'Monthly Detail'!$B$3:$B$92,"Import",'Monthly Detail'!$C$3:$C$92,"Dried deer velvet",'Monthly Detail'!$D$3:$D$92,$A7) -> 2353.45 | F7: =SUMIFS('Monthly Detail'!$AC$3:$AC$92,'Monthly Detail'!$A$3:$A$92,2021,'Monthly Detail'!$B$3:$B$92,"Import",'Monthly Detail'!$C$3:$C$92,"Dried deer velvet",'Monthly Detail'!$D$3:$D$92,$A7) -> 4 | G7: =SUMIFS('Monthly Detail'!$AD$3:$AD$92,'Monthly Detail'!$A$3:$A$92,2021,'Monthly Detail'!$B$3:$B$92,"Import",'Monthly Detail'!$C$3:$C$92,"Dried deer velvet",'Monthly Detail'!$D$3:$D$92,$A7) -> 1428 | H7: =SUMIFS('Monthly Detail'!$AC$3:$AC$92,'Monthly Detail'!$A$3:$A$92,2022,'Monthly Detail'!$B$3:$B$92,"Import",'Monthly Detail'!$C$3:$C$92,"Dried deer velvet",'Monthly Detail'!$D$3:$D$92,$A7) -> 6 | I7: =SUMIFS('Monthly Detail'!$AD$3:$AD$92,'Monthly Detail'!$A$3:$A$92,2022,'Monthly Detail'!$B$3:$B$92,"Import",'Monthly Detail'!$C$3:$C$92,"Dried deer velvet",'Monthly Detail'!$D$3:$D$92,$A7) -> 2096.8 | J7: =SUMIFS('Monthly Detail'!$AC$3:$AC$92,'Monthly Detail'!$A$3:$A$92,2023,'Monthly Detail'!$B$3:$B$92,"Import",'Monthly Detail'!$C$3:$C$92,"Dried deer velvet",'Monthly Detail'!$D$3:$D$92,$A7) -> 4 | K7: =SUMIFS('Monthly Detail'!$AD$3:$AD$92,'Monthly Detail'!$A$3:$A$92,2023,'Monthly Detail'!$B$3:$B$92,"Import",'Monthly Detail'!$C$3:$C$92,"Dried deer velvet",'Monthly Detail'!$D$3:$D$92,$A7) -> 1094.8 | L7: =SUMIFS('Monthly Detail'!$AC$3:$AC$92,'Monthly Detail'!$A$3:$A$92,2024,'Monthly Detail'!$B$3:$B$92,"Import",'Monthly Detail'!$C$3:$C$92,"Dried deer velvet",'Monthly Detail'!$D$3:$D$92,$A7) -> 2 | M7: =SUMIFS('Monthly Detail'!$AD$3:$AD$92,'Monthly Detail'!$A$3:$A$92,2024,'Monthly Detail'!$B$3:$B$92,"Import",'Monthly Detail'!$C$3:$C$92,"Dried deer velvet",'Monthly Detail'!$D$3:$D$92,$A7) -> 413 | N7: =SUMIFS('Monthly Detail'!$AC$3:$AC$92,'Monthly Detail'!$A$3:$A$92,2025,'Monthly Detail'!$B$3:$B$92,"Import",'Monthly Detail'!$C$3:$C$92,"Dried deer velvet",'Monthly Detail'!$D$3:$D$92,$A7) -> 2 | O7: =SUMIFS('Monthly Detail'!$AD$3:$AD$92,'Monthly Detail'!$A$3:$A$92,2025,'Monthly Detail'!$B$3:$B$92,"Import",'Monthly Detail'!$C$3:$C$92,"Dried deer velvet",'Monthly Detail'!$D$3:$D$92,$A7) -> 1058 | P7: =SUMIFS('Monthly Detail'!$AC$3:$AC$92,'Monthly Detail'!$A$3:$A$92,2026,'Monthly Detail'!$B$3:$B$92,"Import",'Monthly Detail'!$C$3:$C$92,"Dried deer velvet",'Monthly Detail'!$D$3:$D$92,$A7) -> 0 | Q7: =SUMIFS('Monthly Detail'!$AD$3:$AD$92,'Monthly Detail'!$A$3:$A$92,2026,'Monthly Detail'!$B$3:$B$92,"Import",'Monthly Detail'!$C$3:$C$92,"Dried deer velvet",'Monthly Detail'!$D$3:$D$92,$A7) -> 0
A8: Mongolia | B8: =SUMIFS('Monthly Detail'!$AC$3:$AC$92,'Monthly Detail'!$A$3:$A$92,2019,'Monthly Detail'!$B$3:$B$92,"Import",'Monthly Detail'!$C$3:$C$92,"Dried deer velvet",'Monthly Detail'!$D$3:$D$92,$A8) -> 0 | C8: =SUMIFS('Monthly Detail'!$AD$3:$AD$92,'Monthly Detail'!$A$3:$A$92,2019,'Monthly Detail'!$B$3:$B$92,"Import",'Monthly Detail'!$C$3:$C$92,"Dried deer velvet",'Monthly Detail'!$D$3:$D$92,$A8) -> 0 | D8: =SUMIFS('Monthly Detail'!$AC$3:$AC$92,'Monthly Detail'!$A$3:$A$92,2020,'Monthly Detail'!$B$3:$B$92,"Import",'Monthly Detail'!$C$3:$C$92,"Dried deer velvet",'Monthly Detail'!$D$3:$D$92,$A8) -> 0 | E8: =SUMIFS('Monthly Detail'!$AD$3:$AD$92,'Monthly Detail'!$A$3:$A$92,2020,'Monthly Detail'!$B$3:$B$92,"Import",'Monthly Detail'!$C$3:$C$92,"Dried deer velvet",'Monthly Detail'!$D$3:$D$92,$A8) -> 0 | F8: =SUMIFS('Monthly Detail'!$AC$3:$AC$92,'Monthly Detail'!$A$3:$A$92,2021,'Monthly Detail'!$B$3:$B$92,"Import",'Monthly Detail'!$C$3:$C$92,"Dried deer velvet",'Monthly Detail'!$D$3:$D$92,$A8) -> 0 | G8: =SUMIFS('Monthly Detail'!$AD$3:$AD$92,'Monthly Detail'!$A$3:$A$92,2021,'Monthly Detail'!$B$3:$B$92,"Import",'Monthly Detail'!$C$3:$C$92,"Dried deer velvet",'Monthly Detail'!$D$3:$D$92,$A8) -> 0 | H8: =SUMIFS('Monthly Detail'!$AC$3:$AC$92,'Monthly Detail'!$A$3:$A$92,2022,'Monthly Detail'!$B$3:$B$92,"Import",'Monthly Detail'!$C$3:$C$92,"Dried deer velvet",'Monthly Detail'!$D$3:$D$92,$A8) -> 0 | I8: =SUMIFS('Monthly Detail'!$AD$3:$AD$92,'Monthly Detail'!$A$3:$A$92,2022,'Monthly Detail'!$B$3:$B$92,"Import",'Monthly Detail'!$C$3:$C$92,"Dried deer velvet",'Monthly Detail'!$D$3:$D$92,$A8) -> 0 | J8: =SUMIFS('Monthly Detail'!$AC$3:$AC$92,'Monthly Detail'!$A$3:$A$92,2023,'Monthly Detail'!$B$3:$B$92,"Import",'Monthly Detail'!$C$3:$C$92,"Dried deer velvet",'Monthly Detail'!$D$3:$D$92,$A8) -> 0 | K8: =SUMIFS('Monthly Detail'!$AD$3:$AD$92,'Monthly Detail'!$A$3:$A$92,2023,'Monthly Detail'!$B$3:$B$92,"Import",'Monthly Detail'!$C$3:$C$92,"Dried deer velvet",'Monthly Detail'!$D$3:$D$92,$A8) -> 0 | L8: =SUMIFS('Monthly Detail'!$AC$3:$AC$92,'Monthly Detail'!$A$3:$A$92,2024,'Monthly Detail'!$B$3:$B$92,"Import",'Monthly Detail'!$C$3:$C$92,"Dried deer velvet",'Monthly Detail'!$D$3:$D$92,$A8) -> 0 | M8: =SUMIFS('Monthly Detail'!$AD$3:$AD$92,'Monthly Detail'!$A$3:$A$92,2024,'Monthly Detail'!$B$3:$B$92,"Import",'Monthly Detail'!$C$3:$C$92,"Dried deer velvet",'Monthly Detail'!$D$3:$D$92,$A8) -> 0 | N8: =SUMIFS('Monthly Detail'!$AC$3:$AC$92,'Monthly Detail'!$A$3:$A$92,2025,'Monthly Detail'!$B$3:$B$92,"Import",'Monthly Detail'!$C$3:$C$92,"Dried deer velvet",'Monthly Detail'!$D$3:$D$92,$A8) -> 0 | O8: =SUMIFS('Monthly Detail'!$AD$3:$AD$92,'Monthly Detail'!$A$3:$A$92,2025,'Monthly Detail'!$B$3:$B$92,"Import",'Monthly Detail'!$C$3:$C$92,"Dried deer velvet",'Monthly Detail'!$D$3:$D$92,$A8) -> 0 | P8: =SUMIFS('Monthly Detail'!$AC$3:$AC$92,'Monthly Detail'!$A$3:$A$92,2026,'Monthly Detail'!$B$3:$B$92,"Import",'Monthly Detail'!$C$3:$C$92,"Dried deer velvet",'Monthly Detail'!$D$3:$D$92,$A8) -> 1 | Q8: =SUMIFS('Monthly Detail'!$AD$3:$AD$92,'Monthly Detail'!$A$3:$A$92,2026,'Monthly Detail'!$B$3:$B$92,"Import",'Monthly Detail'!$C$3:$C$92,"Dried deer velvet",'Monthly Detail'!$D$3:$D$92,$A8) -> 0.3
A9: New Zealand | B9: =SUMIFS('Monthly Detail'!$AC$3:$AC$92,'Monthly Detail'!$A$3:$A$92,2019,'Monthly Detail'!$B$3:$B$92,"Import",'Monthly Detail'!$C$3:$C$92,"Dried deer velvet",'Monthly Detail'!$D$3:$D$92,$A9) -> 34 | C9: =SUMIFS('Monthly Detail'!$AD$3:$AD$92,'Monthly Detail'!$A$3:$A$92,2019,'Monthly Detail'!$B$3:$B$92,"Import",'Monthly Detail'!$C$3:$C$92,"Dried deer velvet",'Monthly Detail'!$D$3:$D$92,$A9) -> 44020.54 | D9: =SUMIFS('Monthly Detail'!$AC$3:$AC$92,'Monthly Detail'!$A$3:$A$92,2020,'Monthly Detail'!$B$3:$B$92,"Import",'Monthly Detail'!$C$3:$C$92,"Dried deer velvet",'Monthly Detail'!$D$3:$D$92,$A9) -> 32 | E9: =SUMIFS('Monthly Detail'!$AD$3:$AD$92,'Monthly Detail'!$A$3:$A$92,2020,'Monthly Detail'!$B$3:$B$92,"Import",'Monthly Detail'!$C$3:$C$92,"Dried deer velvet",'Monthly Detail'!$D$3:$D$92,$A9) -> 37625.946 | F9: =SUMIFS('Monthly Detail'!$AC$3:$AC$92,'Monthly Detail'!$A$3:$A$92,2021,'Monthly Detail'!$B$3:$B$92,"Import",'Monthly Detail'!$C$3:$C$92,"Dried deer velvet",'Monthly Detail'!$D$3:$D$92,$A9) -> 26 | G9: =SUMIFS('Monthly Detail'!$AD$3:$AD$92,'Monthly Detail'!$A$3:$A$92,2021,'Monthly Detail'!$B$3:$B$92,"Import",'Monthly Detail'!$C$3:$C$92,"Dried deer velvet",'Monthly Detail'!$D$3:$D$92,$A9) -> 24123.93 | H9: =SUMIFS('Monthly Detail'!$AC$3:$AC$92,'Monthly Detail'!$A$3:$A$92,2022,'Monthly Detail'!$B$3:$B$92,"Import",'Monthly Detail'!$C$3:$C$92,"Dried deer velvet",'Monthly Detail'!$D$3:$D$92,$A9) -> 29 | I9: =SUMIFS('Monthly Detail'!$AD$3:$AD$92,'Monthly Detail'!$A$3:$A$92,2022,'Monthly Detail'!$B$3:$B$92,"Import",'Monthly Detail'!$C$3:$C$92,"Dried deer velvet",'Monthly Detail'!$D$3:$D$92,$A9) -> 39451.19 | J9: =SUMIFS('Monthly Detail'!$AC$3:$AC$92,'Monthly Detail'!$A$3:$A$92,2023,'Monthly Detail'!$B$3:$B$92,"Import",'Monthly Detail'!$C$3:$C$92,"Dried deer velvet",'Monthly Detail'!$D$3:$D$92,$A9) -> 29 | K9: =SUMIFS('Monthly Detail'!$AD$3:$AD$92,'Monthly Detail'!$A$3:$A$92,2023,'Monthly Detail'!$B$3:$B$92,"Import",'Monthly Detail'!$C$3:$C$92,"Dried deer velvet",'Monthly Detail'!$D$3:$D$92,$A9) -> 47828.31 | L9: =SUMIFS('Monthly Detail'!$AC$3:$AC$92,'Monthly Detail'!$A$3:$A$92,2024,'Monthly Detail'!$B$3:$B$92,"Import",'Monthly Detail'!$C$3:$C$92,"Dried deer velvet",'Monthly Detail'!$D$3:$D$92,$A9) -> 11 | M9: =SUMIFS('Monthly Detail'!$AD$3:$AD$92,'Monthly Detail'!$A$3:$A$92,2024,'Monthly Detail'!$B$3:$B$92,"Import",'Monthly Detail'!$C$3:$C$92,"Dried deer velvet",'Monthly Detail'!$D$3:$D$92,$A9) -> 16787.61 | N9: =SUMIFS('Monthly Detail'!$AC$3:$AC$92,'Monthly Detail'!$A$3:$A$92,2025,'Monthly Detail'!$B$3:$B$92,"Import",'Monthly Detail'!$C$3:$C$92,"Dried deer velvet",'Monthly Detail'!$D$3:$D$92,$A9) -> 8 | O9: =SUMIFS('Monthly Detail'!$AD$3:$AD$92,'Monthly Detail'!$A$3:$A$92,2025,'Monthly Detail'!$B$3:$B$92,"Import",'Monthly Detail'!$C$3:$C$92,"Dried deer velvet",'Monthly Detail'!$D$3:$D$92,$A9) -> 8812.76 | P9: =SUMIFS('Monthly Detail'!$AC$3:$AC$92,'Monthly Detail'!$A$3:$A$92,2026,'Monthly Detail'!$B$3:$B$92,"Import",'Monthly Detail'!$C$3:$C$92,"Dried deer velvet",'Monthly Detail'!$D$3:$D$92,$A9) -> 148 | Q9: =SUMIFS('Monthly Detail'!$AD$3:$AD$92,'Monthly Detail'!$A$3:$A$92,2026,'Monthly Detail'!$B$3:$B$92,"Import",'Monthly Detail'!$C$3:$C$92,"Dried deer velvet",'Monthly Detail'!$D$3:$D$92,$A9) -> 3674
A10: Russia | B10: =SUMIFS('Monthly Detail'!$AC$3:$AC$92,'Monthly Detail'!$A$3:$A$92,2019,'Monthly Detail'!$B$3:$B$92,"Import",'Monthly Detail'!$C$3:$C$92,"Dried deer velvet",'Monthly Detail'!$D$3:$D$92,$A10) -> 48 | C10: =SUMIFS('Monthly Detail'!$AD$3:$AD$92,'Monthly Detail'!$A$3:$A$92,2019,'Monthly Detail'!$B$3:$B$92,"Import",'Monthly Detail'!$C$3:$C$92,"Dried deer velvet",'Monthly Detail'!$D$3:$D$92,$A10) -> 46436 | D10: =SUMIFS('Monthly Detail'!$AC$3:$AC$92,'Monthly Detail'!$A$3:$A$92,2020,'Monthly Detail'!$B$3:$B$92,"Import",'Monthly Detail'!$C$3:$C$92,"Dried deer velvet",'Monthly Detail'!$D$3:$D$92,$A10) -> 58 | E10: =SUMIFS('Monthly Detail'!$AD$3:$AD$92,'Monthly Detail'!$A$3:$A$92,2020,'Monthly Detail'!$B$3:$B$92,"Import",'Monthly Detail'!$C$3:$C$92,"Dried deer velvet",'Monthly Detail'!$D$3:$D$92,$A10) -> 54041.45 | F10: =SUMIFS('Monthly Detail'!$AC$3:$AC$92,'Monthly Detail'!$A$3:$A$92,2021,'Monthly Detail'!$B$3:$B$92,"Import",'Monthly Detail'!$C$3:$C$92,"Dried deer velvet",'Monthly Detail'!$D$3:$D$92,$A10) -> 44 | G10: =SUMIFS('Monthly Detail'!$AD$3:$AD$92,'Monthly Detail'!$A$3:$A$92,2021,'Monthly Detail'!$B$3:$B$92,"Import",'Monthly Detail'!$C$3:$C$92,"Dried deer velvet",'Monthly Detail'!$D$3:$D$92,$A10) -> 55980.19 | H10: =SUMIFS('Monthly Detail'!$AC$3:$AC$92,'Monthly Detail'!$A$3:$A$92,2022,'Monthly Detail'!$B$3:$B$92,"Import",'Monthly Detail'!$C$3:$C$92,"Dried deer velvet",'Monthly Detail'!$D$3:$D$92,$A10) -> 32 | I10: =SUMIFS('Monthly Detail'!$AD$3:$AD$92,'Monthly Detail'!$A$3:$A$92,2022,'Monthly Detail'!$B$3:$B$92,"Import",'Monthly Detail'!$C$3:$C$92,"Dried deer velvet",'Monthly Detail'!$D$3:$D$92,$A10) -> 43889.1 | J10: =SUMIFS('Monthly Detail'!$AC$3:$AC$92,'Monthly Detail'!$A$3:$A$92,2023,'Monthly Detail'!$B$3:$B$92,"Import",'Monthly Detail'!$C$3:$C$92,"Dried deer velvet",'Monthly Detail'!$D$3:$D$92,$A10) -> 29 | K10: =SUMIFS('Monthly Detail'!$AD$3:$AD$92,'Monthly Detail'!$A$3:$A$92,2023,'Monthly Detail'!$B$3:$B$92,"Import",'Monthly Detail'!$C$3:$C$92,"Dried deer velvet",'Monthly Detail'!$D$3:$D$92,$A10) -> 29108.59 | L10: =SUMIFS('Monthly Detail'!$AC$3:$AC$92,'Monthly Detail'!$A$3:$A$92,2024,'Monthly Detail'!$B$3:$B$92,"Import",'Monthly Detail'!$C$3:$C$92,"Dried deer velvet",'Monthly Detail'!$D$3:$D$92,$A10) -> 41 | M10: =SUMIFS('Monthly Detail'!$AD$3:$AD$92,'Monthly Detail'!$A$3:$A$92,2024,'Monthly Detail'!$B$3:$B$92,"Import",'Monthly Detail'!$C$3:$C$92,"Dried deer velvet",'Monthly Detail'!$D$3:$D$92,$A10) -> 39859.82 | N10: =SUMIFS('Monthly Detail'!$AC$3:$AC$92,'Monthly Detail'!$A$3:$A$92,2025,'Monthly Detail'!$B$3:$B$92,"Import",'Monthly Detail'!$C$3:$C$92,"Dried deer velvet",'Monthly Detail'!$D$3:$D$92,$A10) -> 37 | O10: =SUMIFS('Monthly Detail'!$AD$3:$AD$92,'Monthly Detail'!$A$3:$A$92,2025,'Monthly Detail'!$B$3:$B$92,"Import",'Monthly Detail'!$C$3:$C$92,"Dried deer velvet",'Monthly Detail'!$D$3:$D$92,$A10) -> 36440.51 | P10: =SUMIFS('Monthly Detail'!$AC$3:$AC$92,'Monthly Detail'!$A$3:$A$92,2026,'Monthly Detail'!$B$3:$B$92,"Import",'Monthly Detail'!$C$3:$C$92,"Dried deer velvet",'Monthly Detail'!$D$3:$D$92,$A10) -> 21 | Q10: =SUMIFS('Monthly Detail'!$AD$3:$AD$92,'Monthly Detail'!$A$3:$A$92,2026,'Monthly Detail'!$B$3:$B$92,"Import",'Monthly Detail'!$C$3:$C$92,"Dried deer velvet",'Monthly Detail'!$D$3:$D$92,$A10) -> 21258.7
A11: Singapore | B11: =SUMIFS('Monthly Detail'!$AC$3:$AC$92,'Monthly Detail'!$A$3:$A$92,2019,'Monthly Detail'!$B$3:$B$92,"Import",'Monthly Detail'!$C$3:$C$92,"Dried deer velvet",'Monthly Detail'!$D$3:$D$92,$A11) -> 1 | C11: =SUMIFS('Monthly Detail'!$AD$3:$AD$92,'Monthly Detail'!$A$3:$A$92,2019,'Monthly Detail'!$B$3:$B$92,"Import",'Monthly Detail'!$C$3:$C$92,"Dried deer velvet",'Monthly Detail'!$D$3:$D$92,$A11) -> 500 | D11: =SUMIFS('Monthly Detail'!$AC$3:$AC$92,'Monthly Detail'!$A$3:$A$92,2020,'Monthly Detail'!$B$3:$B$92,"Import",'Monthly Detail'!$C$3:$C$92,"Dried deer velvet",'Monthly Detail'!$D$3:$D$92,$A11) -> 0 | E11: =SUMIFS('Monthly Detail'!$AD$3:$AD$92,'Monthly Detail'!$A$3:$A$92,2020,'Monthly Detail'!$B$3:$B$92,"Import",'Monthly Detail'!$C$3:$C$92,"Dried deer velvet",'Monthly Detail'!$D$3:$D$92,$A11) -> 0 | F11: =SUMIFS('Monthly Detail'!$AC$3:$AC$92,'Monthly Detail'!$A$3:$A$92,2021,'Monthly Detail'!$B$3:$B$92,"Import",'Monthly Detail'!$C$3:$C$92,"Dried deer velvet",'Monthly Detail'!$D$3:$D$92,$A11) -> 0 | G11: =SUMIFS('Monthly Detail'!$AD$3:$AD$92,'Monthly Detail'!$A$3:$A$92,2021,'Monthly Detail'!$B$3:$B$92,"Import",'Monthly Detail'!$C$3:$C$92,"Dried deer velvet",'Monthly Detail'!$D$3:$D$92,$A11) -> 0 | H11: =SUMIFS('Monthly Detail'!$AC$3:$AC$92,'Monthly Detail'!$A$3:$A$92,2022,'Monthly Detail'!$B$3:$B$92,"Import",'Monthly Detail'!$C$3:$C$92,"Dried deer velvet",'Monthly Detail'!$D$3:$D$92,$A11) -> 0 | I11: =SUMIFS('Monthly Detail'!$AD$3:$AD$92,'Monthly Detail'!$A$3:$A$92,2022,'Monthly Detail'!$B$3:$B$92,"Import",'Monthly Detail'!$C$3:$C$92,"Dried deer velvet",'Monthly Detail'!$D$3:$D$92,$A11) -> 0 | J11: =SUMIFS('Monthly Detail'!$AC$3:$AC$92,'Monthly Detail'!$A$3:$A$92,2023,'Monthly Detail'!$B$3:$B$92,"Import",'Monthly Detail'!$C$3:$C$92,"Dried deer velvet",'Monthly Detail'!$D$3:$D$92,$A11) -> 0 | K11: =SUMIFS('Monthly Detail'!$AD$3:$AD$92,'Monthly Detail'!$A$3:$A$92,2023,'Monthly Detail'!$B$3:$B$92,"Import",'Monthly Detail'!$C$3:$C$92,"Dried deer velvet",'Monthly Detail'!$D$3:$D$92,$A11) -> 0 | L11: =SUMIFS('Monthly Detail'!$AC$3:$AC$92,'Monthly Detail'!$A$3:$A$92,2024,'Monthly Detail'!$B$3:$B$92,"Import",'Monthly Detail'!$C$3:$C$92,"Dried deer velvet",'Monthly Detail'!$D$3:$D$92,$A11) -> 0 | M11: =SUMIFS('Monthly Detail'!$AD$3:$AD$92,'Monthly Detail'!$A$3:$A$92,2024,'Monthly Detail'!$B$3:$B$92,"Import",'Monthly Detail'!$C$3:$C$92,"Dried deer velvet",'Monthly Detail'!$D$3:$D$92,$A11) -> 0 | N11: =SUMIFS('Monthly Detail'!$AC$3:$AC$92,'Monthly Detail'!$A$3:$A$92,2025,'Monthly Detail'!$B$3:$B$92,"Import",'Monthly Detail'!$C$3:$C$92,"Dried deer velvet",'Monthly Detail'!$D$3:$D$92,$A11) -> 0 | O11: =SUMIFS('Monthly Detail'!$AD$3:$AD$92,'Monthly Detail'!$A$3:$A$92,2025,'Monthly Detail'!$B$3:$B$92,"Import",'Monthly Detail'!$C$3:$C$92,"Dried deer velvet",'Monthly Detail'!$D$3:$D$92,$A11) -> 0 | P11: =SUMIFS('Monthly Detail'!$AC$3:$AC$92,'Monthly Detail'!$A$3:$A$92,2026,'Monthly Detail'!$B$3:$B$92,"Import",'Monthly Detail'!$C$3:$C$92,"Dried deer velvet",'Monthly Detail'!$D$3:$D$92,$A11) -> 0 | Q11: =SUMIFS('Monthly Detail'!$AD$3:$AD$92,'Monthly Detail'!$A$3:$A$92,2026,'Monthly Detail'!$B$3:$B$92,"Import",'Monthly Detail'!$C$3:$C$92,"Dried deer velvet",'Monthly Detail'!$D$3:$D$92,$A11) -> 0
A12: USA | B12: =SUMIFS('Monthly Detail'!$AC$3:$AC$92,'Monthly Detail'!$A$3:$A$92,2019,'Monthly Detail'!$B$3:$B$92,"Import",'Monthly Detail'!$C$3:$C$92,"Dried deer velvet",'Monthly Detail'!$D$3:$D$92,$A12) -> 0 | C12: =SUMIFS('Monthly Detail'!$AD$3:$AD$92,'Monthly Detail'!$A$3:$A$92,2019,'Monthly Detail'!$B$3:$B$92,"Import",'Monthly Detail'!$C$3:$C$92,"Dried deer velvet",'Monthly Detail'!$D$3:$D$92,$A12) -> 0 | D12: =SUMIFS('Monthly Detail'!$AC$3:$AC$92,'Monthly Detail'!$A$3:$A$92,2020,'Monthly Detail'!$B$3:$B$92,"Import",'Monthly Detail'!$C$3:$C$92,"Dried deer velvet",'Monthly Detail'!$D$3:$D$92,$A12) -> 0 | E12: =SUMIFS('Monthly Detail'!$AD$3:$AD$92,'Monthly Detail'!$A$3:$A$92,2020,'Monthly Detail'!$B$3:$B$92,"Import",'Monthly Detail'!$C$3:$C$92,"Dried deer velvet",'Monthly Detail'!$D$3:$D$92,$A12) -> 0 | F12: =SUMIFS('Monthly Detail'!$AC$3:$AC$92,'Monthly Detail'!$A$3:$A$92,2021,'Monthly Detail'!$B$3:$B$92,"Import",'Monthly Detail'!$C$3:$C$92,"Dried deer velvet",'Monthly Detail'!$D$3:$D$92,$A12) -> 0 | G12: =SUMIFS('Monthly Detail'!$AD$3:$AD$92,'Monthly Detail'!$A$3:$A$92,2021,'Monthly Detail'!$B$3:$B$92,"Import",'Monthly Detail'!$C$3:$C$92,"Dried deer velvet",'Monthly Detail'!$D$3:$D$92,$A12) -> 0 | H12: =SUMIFS('Monthly Detail'!$AC$3:$AC$92,'Monthly Detail'!$A$3:$A$92,2022,'Monthly Detail'!$B$3:$B$92,"Import",'Monthly Detail'!$C$3:$C$92,"Dried deer velvet",'Monthly Detail'!$D$3:$D$92,$A12) -> 0 | I12: =SUMIFS('Monthly Detail'!$AD$3:$AD$92,'Monthly Detail'!$A$3:$A$92,2022,'Monthly Detail'!$B$3:$B$92,"Import",'Monthly Detail'!$C$3:$C$92,"Dried deer velvet",'Monthly Detail'!$D$3:$D$92,$A12) -> 0 | J12: =SUMIFS('Monthly Detail'!$AC$3:$AC$92,'Monthly Detail'!$A$3:$A$92,2023,'Monthly Detail'!$B$3:$B$92,"Import",'Monthly Detail'!$C$3:$C$92,"Dried deer velvet",'Monthly Detail'!$D$3:$D$92,$A12) -> 0 | K12: =SUMIFS('Monthly Detail'!$AD$3:$AD$92,'Monthly Detail'!$A$3:$A$92,2023,'Monthly Detail'!$B$3:$B$92,"Import",'Monthly Detail'!$C$3:$C$92,"Dried deer velvet",'Monthly Detail'!$D$3:$D$92,$A12) -> 0 | L12: =SUMIFS('Monthly Detail'!$AC$3:$AC$92,'Monthly Detail'!$A$3:$A$92,2024,'Monthly Detail'!$B$3:$B$92,"Import",'Monthly Detail'!$C$3:$C$92,"Dried deer velvet",'Monthly Detail'!$D$3:$D$92,$A12) -> 0 | M12: =SUMIFS('Monthly Detail'!$AD$3:$AD$92,'Monthly Detail'!$A$3:$A$92,2024,'Monthly Detail'!$B$3:$B$92,"Import",'Monthly Detail'!$C$3:$C$92,"Dried deer velvet",'Monthly Detail'!$D$3:$D$92,$A12) -> 0 | N12: =SUMIFS('Monthly Detail'!$AC$3:$AC$92,'Monthly Detail'!$A$3:$A$92,2025,'Monthly Detail'!$B$3:$B$92,"Import",'Monthly Detail'!$C$3:$C$92,"Dried deer velvet",'Monthly Detail'!$D$3:$D$92,$A12) -> 0 | O12: =SUMIFS('Monthly Detail'!$AD$3:$AD$92,'Monthly Detail'!$A$3:$A$92,2025,'Monthly Detail'!$B$3:$B$92,"Import",'Monthly Detail'!$C$3:$C$92,"Dried deer velvet",'Monthly Detail'!$D$3:$D$92,$A12) -> 0 | P12: =SUMIFS('Monthly Detail'!$AC$3:$AC$92,'Monthly Detail'!$A$3:$A$92,2026,'Monthly Detail'!$B$3:$B$92,"Import",'Monthly Detail'!$C$3:$C$92,"Dried deer velvet",'Monthly Detail'!$D$3:$D$92,$A12) -> 5 | Q12: =SUMIFS('Monthly Detail'!$AD$3:$AD$92,'Monthly Detail'!$A$3:$A$92,2026,'Monthly Detail'!$B$3:$B$92,"Import",'Monthly Detail'!$C$3:$C$92,"Dried deer velvet",'Monthly Detail'!$D$3:$D$92,$A12) -> 1.8
A13: Total | B13: =SUM(B3:B12) -> 182 | C13: =SUM(C3:C12) -> 175157.05 | D13: =SUM(D3:D12) -> 203 | E13: =SUM(E3:E12) -> 185376.86 | F13: =SUM(F3:F12) -> 165 | G13: =SUM(G3:G12) -> 176389.62 | H13: =SUM(H3:H12) -> 152 | I13: =SUM(I3:I12) -> 198823.52 | ... Q13: =SUM(Q3:Q12) -> 63264.1
A16: Import — Frozen deer velvet: Annual Quarantine Results by Country
A17: Country | B17: 2019 Cases | C17: 2019 Qty (kg) | D17: 2020 Cases | E17: 2020 Qty (kg) | F17: 2021 Cases | G17: 2021 Qty (kg) | H17: 2022 Cases | I17: 2022 Qty (kg) | J17: 2023 Cases | K17: 2023 Qty (kg) | L17: 2024 Cases | M17: 2024 Qty (kg) | N17: 2025 Cases | O17: 2025 Qty (kg) | P17: 2026* Cases | Q17: 2026* Qty (kg)
A18: China | B18: =SUMIFS('Monthly Detail'!$AC$3:$AC$92,'Monthly Detail'!$A$3:$A$92,2019,'Monthly Detail'!$B$3:$B$92,"Import",'Monthly Detail'!$C$3:$C$92,"Frozen deer velvet",'Monthly Detail'!$D$3:$D$92,$A18) -> 0 | C18: =SUMIFS('Monthly Detail'!$AD$3:$AD$92,'Monthly Detail'!$A$3:$A$92,2019,'Monthly Detail'!$B$3:$B$92,"Import",'Monthly Detail'!$C$3:$C$92,"Frozen deer velvet",'Monthly Detail'!$D$3:$D$92,$A18) -> 0 | D18: =SUMIFS('Monthly Detail'!$AC$3:$AC$92,'Monthly Detail'!$A$3:$A$92,2020,'Monthly Detail'!$B$3:$B$92,"Import",'Monthly Detail'!$C$3:$C$92,"Frozen deer velvet",'Monthly Detail'!$D$3:$D$92,$A18) -> 0 | E18: =SUMIFS('Monthly Detail'!$AD$3:$AD$92,'Monthly Detail'!$A$3:$A$92,2020,'Monthly Detail'!$B$3:$B$92,"Import",'Monthly Detail'!$C$3:$C$92,"Frozen deer velvet",'Monthly Detail'!$D$3:$D$92,$A18) -> 0 | F18: =SUMIFS('Monthly Detail'!$AC$3:$AC$92,'Monthly Detail'!$A$3:$A$92,2021,'Monthly Detail'!$B$3:$B$92,"Import",'Monthly Detail'!$C$3:$C$92,"Frozen deer velvet",'Monthly Detail'!$D$3:$D$92,$A18) -> 0 | G18: =SUMIFS('Monthly Detail'!$AD$3:$AD$92,'Monthly Detail'!$A$3:$A$92,2021,'Monthly Detail'!$B$3:$B$92,"Import",'Monthly Detail'!$C$3:$C$92,"Frozen deer velvet",'Monthly Detail'!$D$3:$D$92,$A18) -> 0 | H18: =SUMIFS('Monthly Detail'!$AC$3:$AC$92,'Monthly Detail'!$A$3:$A$92,2022,'Monthly Detail'!$B$3:$B$92,"Import",'Monthly Detail'!$C$3:$C$92,"Frozen deer velvet",'Monthly Detail'!$D$3:$D$92,$A18) -> 0 | I18: =SUMIFS('Monthly Detail'!$AD$3:$AD$92,'Monthly Detail'!$A$3:$A$92,2022,'Monthly Detail'!$B$3:$B$92,"Import",'Monthly Detail'!$C$3:$C$92,"Frozen deer velvet",'Monthly Detail'!$D$3:$D$92,$A18) -> 0 | J18: =SUMIFS('Monthly Detail'!$AC$3:$AC$92,'Monthly Detail'!$A$3:$A$92,2023,'Monthly Detail'!$B$3:$B$92,"Import",'Monthly Detail'!$C$3:$C$92,"Frozen deer velvet",'Monthly Detail'!$D$3:$D$92,$A18) -> 0 | K18: =SUMIFS('Monthly Detail'!$AD$3:$AD$92,'Monthly Detail'!$A$3:$A$92,2023,'Monthly Detail'!$B$3:$B$92,"Import",'Monthly Detail'!$C$3:$C$92,"Frozen deer velvet",'Monthly Detail'!$D$3:$D$92,$A18) -> 0 | L18: =SUMIFS('Monthly Detail'!$AC$3:$AC$92,'Monthly Detail'!$A$3:$A$92,2024,'Monthly Detail'!$B$3:$B$92,"Import",'Monthly Detail'!$C$3:$C$92,"Frozen deer velvet",'Monthly Detail'!$D$3:$D$92,$A18) -> 1 | M18: =SUMIFS('Monthly Detail'!$AD$3:$AD$92,'Monthly Detail'!$A$3:$A$92,2024,'Monthly Detail'!$B$3:$B$92,"Import",'Monthly Detail'!$C$3:$C$92,"Frozen deer velvet",'Monthly Detail'!$D$3:$D$92,$A18) -> 400 | N18: =SUMIFS('Monthly Detail'!$AC$3:$AC$92,'Monthly Detail'!$A$3:$A$92,2025,'Monthly Detail'!$B$3:$B$92,"Import",'Monthly Detail'!$C$3:$C$92,"Frozen deer velvet",'Monthly Detail'!$D$3:$D$92,$A18) -> 2 | O18: =SUMIFS('Monthly Detail'!$AD$3:$AD$92,'Monthly Detail'!$A$3:$A$92,2025,'Monthly Detail'!$B$3:$B$92,"Import",'Monthly Detail'!$C$3:$C$92,"Frozen deer velvet",'Monthly Detail'!$D$3:$D$92,$A18) -> 1350 | P18: =SUMIFS('Monthly Detail'!$AC$3:$AC$92,'Monthly Detail'!$A$3:$A$92,2026,'Monthly Detail'!$B$3:$B$92,"Import",'Monthly Detail'!$C$3:$C$92,"Frozen deer velvet",'Monthly Detail'!$D$3:$D$92,$A18) -> 0 | Q18: =SUMIFS('Monthly Detail'!$AD$3:$AD$92,'Monthly Detail'!$A$3:$A$92,2026,'Monthly Detail'!$B$3:$B$92,"Import",'Monthly Detail'!$C$3:$C$92,"Frozen deer velvet",'Monthly Detail'!$D$3:$D$92,$A18) -> 0
A19: New Zealand | B19: =SUMIFS('Monthly Detail'!$AC$3:$AC$92,'Monthly Detail'!$A$3:$A$92,2019,'Monthly Detail'!$B$3:$B$92,"Import",'Monthly Detail'!$C$3:$C$92,"Frozen deer velvet",'Monthly Detail'!$D$3:$D$92,$A19) -> 28 | C19: =SUMIFS('Monthly Detail'!$AD$3:$AD$92,'Monthly Detail'!$A$3:$A$92,2019,'Monthly Detail'!$B$3:$B$92,"Import",'Monthly Detail'!$C$3:$C$92,"Frozen deer velvet",'Monthly Detail'!$D$3:$D$92,$A19) -> 99112.97 | D19: =SUMIFS('Monthly Detail'!$AC$3:$AC$92,'Monthly Detail'!$A$3:$A$92,2020,'Monthly Detail'!$B$3:$B$92,"Import",'Monthly Detail'!$C$3:$C$92,"Frozen deer velvet",'Monthly Detail'!$D$3:$D$92,$A19) -> 22 | E19: =SUMIFS('Monthly Detail'!$AD$3:$AD$92,'Monthly Detail'!$A$3:$A$92,2020,'Monthly Detail'!$B$3:$B$92,"Import",'Monthly Detail'!$C$3:$C$92,"Frozen deer velvet",'Monthly Detail'!$D$3:$D$92,$A19) -> 77477.37 | F19: =SUMIFS('Monthly Detail'!$AC$3:$AC$92,'Monthly Detail'!$A$3:$A$92,2021,'Monthly Detail'!$B$3:$B$92,"Import",'Monthly Detail'!$C$3:$C$92,"Frozen deer velvet",'Monthly Detail'!$D$3:$D$92,$A19) -> 25 | G19: =SUMIFS('Monthly Detail'!$AD$3:$AD$92,'Monthly Detail'!$A$3:$A$92,2021,'Monthly Detail'!$B$3:$B$92,"Import",'Monthly Detail'!$C$3:$C$92,"Frozen deer velvet",'Monthly Detail'!$D$3:$D$92,$A19) -> 91874.14 | H19: =SUMIFS('Monthly Detail'!$AC$3:$AC$92,'Monthly Detail'!$A$3:$A$92,2022,'Monthly Detail'!$B$3:$B$92,"Import",'Monthly Detail'!$C$3:$C$92,"Frozen deer velvet",'Monthly Detail'!$D$3:$D$92,$A19) -> 39 | I19: =SUMIFS('Monthly Detail'!$AD$3:$AD$92,'Monthly Detail'!$A$3:$A$92,2022,'Monthly Detail'!$B$3:$B$92,"Import",'Monthly Detail'!$C$3:$C$92,"Frozen deer velvet",'Monthly Detail'!$D$3:$D$92,$A19) -> 116583.79 | J19: =SUMIFS('Monthly Detail'!$AC$3:$AC$92,'Monthly Detail'!$A$3:$A$92,2023,'Monthly Detail'!$B$3:$B$92,"Import",'Monthly Detail'!$C$3:$C$92,"Frozen deer velvet",'Monthly Detail'!$D$3:$D$92,$A19) -> 38 | K19: =SUMIFS('Monthly Detail'!$AD$3:$AD$92,'Monthly Detail'!$A$3:$A$92,2023,'Monthly Detail'!$B$3:$B$92,"Import",'Monthly Detail'!$C$3:$C$92,"Frozen deer velvet",'Monthly Detail'!$D$3:$D$92,$A19) -> 116292.17 | L19: =SUMIFS('Monthly Detail'!$AC$3:$AC$92,'Monthly Detail'!$A$3:$A$92,2024,'Monthly Detail'!$B$3:$B$92,"Import",'Monthly Detail'!$C$3:$C$92,"Frozen deer velvet",'Monthly Detail'!$D$3:$D$92,$A19) -> 31 | M19: =SUMIFS('Monthly Detail'!$AD$3:$AD$92,'Monthly Detail'!$A$3:$A$92,2024,'Monthly Detail'!$B$3:$B$92,"Import",'Monthly Detail'!$C$3:$C$92,"Frozen deer velvet",'Monthly Detail'!$D$3:$D$92,$A19) -> 76938.35 | N19: =SUMIFS('Monthly Detail'!$AC$3:$AC$92,'Monthly Detail'!$A$3:$A$92,2025,'Monthly Detail'!$B$3:$B$92,"Import",'Monthly Detail'!$C$3:$C$92,"Frozen deer velvet",'Monthly Detail'!$D$3:$D$92,$A19) -> 32 | O19: =SUMIFS('Monthly Detail'!$AD$3:$AD$92,'Monthly Detail'!$A$3:$A$92,2025,'Monthly Detail'!$B$3:$B$92,"Import",'Monthly Detail'!$C$3:$C$92,"Frozen deer velvet",'Monthly Detail'!$D$3:$D$92,$A19) -> 94225.13 | P19: =SUMIFS('Monthly Detail'!$AC$3:$AC$92,'Monthly Detail'!$A$3:$A$92,2026,'Monthly Detail'!$B$3:$B$92,"Import",'Monthly Detail'!$C$3:$C$92,"Frozen deer velvet",'Monthly Detail'!$D$3:$D$92,$A19) -> 16 | Q19: =SUMIFS('Monthly Detail'!$AD$3:$AD$92,'Monthly Detail'!$A$3:$A$92,2026,'Monthly Detail'!$B$3:$B$92,"Import",'Monthly Detail'!$C$3:$C$92,"Frozen deer velvet",'Monthly Detail'!$D$3:$D$92,$A19) -> 48628.9
A20: Total | B20: =SUM(B18:B19) -> 28 | C20: =SUM(C18:C19) -> 99112.97 | D20: =SUM(D18:D19) -> 22 | E20: =SUM(E18:E19) -> 77477.37 | F20: =SUM(F18:F19) -> 25 | G20: =SUM(G18:G19) -> 91874.14 | H20: =SUM(H18:H19) -> 39 | I20: =SUM(I18:I19) -> 116583.79 | ... Q20: =SUM(Q18:Q19) -> 48628.9
A23: Export — Dried deer velvet: Annual Quarantine Results by Country
A24: Country | B24: 2019 Cases | C24: 2019 Qty (kg) | D24: 2020 Cases | E24: 2020 Qty (kg) | F24: 2021 Cases | G24: 2021 Qty (kg) | H24: 2022 Cases | I24: 2022 Qty (kg) | J24: 2023 Cases | K24: 2023 Qty (kg) | L24: 2024 Cases | M24: 2024 Qty (kg) | N24: 2025 Cases | O24: 2025 Qty (kg) | P24: 2026* Cases | Q24: 2026* Qty (kg)
