Workbook
Name data: 'import list'!$A$2:$P$599

Sheet Import
A2: Year | B2: 2026
A4: Count of Exporter (English) | B4: Column Labels
A5: Row Labels | B5: China | C5: New Zealand | D5: Russia | E5: Grand Total
A6: Deer velvet (dried) | B6: 1 | C6: 13 | D6: 1 | E6: 15
A7: Bibong Herb | C7: 1 | E7: 1
A8: Chunho N Care | C8: 1 | E8: 1
A9: Eryong Pharm. | B9: 1 | E9: 1
A10: Geonhyang Pharm. | D10: 1 | E10: 1
A11: KNC Deertrade | C11: 3 | E11: 3
A12: OnBio | C12: 1 | E12: 1
A13: Onnuri Bio | C13: 2 | E13: 2
A14: WooSung (Mr Bang) | C14: 3 | E14: 3
A15: Yujin Trade | C15: 2 | E15: 2
A16: Deer velvet (frozen) | C16: 23 | E16: 23
A17: Bio Dot (Han Dong Herb) | C17: 3 | E17: 3
A18: Eryong Pharm. | C18: 2 | E18: 2
A19: HwaYong Pharm. | C19: 3 | E19: 3
A20: KGC | C20: 2 | E20: 2
A21: KNC Deertrade | C21: 5 | E21: 5
A22: OnBio | C22: 2 | E22: 2
... A24: GaOn Pharm | C24: 2 | E24: 2
A25: Grand Total | B25: 1 | C25: 36 | D25: 1 | E25: 38

Sheet Export
A2: Year | B2: 2026
A4: Count of Exporter (English) | B4: Column Labels
A5: Row Labels | B5: 01 | C5: 02 | D5: 03 | E5: 04 | F5: 05 | G5: 06 | H5: 07 | I5: 08 | J5: 09 | K5: 10 | L5: 11 | M5: 12 | N5: Grand Total
A6: China | F6: 1 | N6: 1
A7: Deer velvet (dried) | F7: 1 | N7: 1
A8: TIELING AOLU TRADE CO.,LTD | F8: 1 | N8: 1
A9: New Zealand | B9: 3 | C9: 2 | D9: 12 | E9: 11 | F9: 4 | G9: 4 | N9: 36
A10: Deer velvet (dried) | B10: 1 | D10: 2 | E10: 5 | F10: 2 | G10: 3 | N10: 13
A11: DALIAN CHANG LU DEER INDUSTRY CO., LTD | F11: 1 | G11: 1 | N11: 2
A12: DALIAN HENGLU DEER INDUSTRY CO LTD | D12: 2 | N12: 2
A13: STREAMLANDS EXPORTS NZ LTD | G13: 1 | N13: 1
A14: TIELING AOLU TRADE CO.,LTD | E14: 2 | N14: 2
A15: XIFENG MINHE DEER PRODUCTS CO.,LTD | E15: 3 | N15: 3
A16: DALIAN F.T.Z. JUNFENG INTERNATIONAL INDUSTRIAL & TRADE CO.,LTD. | B16: 1 | F16: 1 | N16: 2
A17: VEXCO LIMITED | G17: 1 | N17: 1
A18: Deer velvet (frozen) | B18: 2 | C18: 2 | D18: 10 | E18: 6 | F18: 2 | G18: 1 | N18: 23
A19: C K IMPORT EXPORT CO (NZ) LTD | B19: 1 | D19: 2 | N19: 3
A20: CK IMPORT EXPORT CO.(NZ) LTD | C20: 1 | E20: 2 | N20: 3
A21: PAREX INTERNATIONAL LTD | D21: 2 | N21: 2
A22: ROKLAND CORPORATION LIMITED | B22: 1 | D22: 2 | E22: 2 | F22: 1 | N22: 6
A23: UB BIO LIMITED | F23: 1 | N23: 1
A24: YIK LUNG TONG(NZ) INTERNAIONAL LIMITED | C24: 1 | D24: 2 | N24: 3
A25: PROVELCO LTD | D25: 2 | N25: 2
A26: CK IMPORT-EXPORT COMPANY NZ LIMITED | E26: 2 | N26: 2
A27: ORIENTAL DEER HOLDINGS LIMITED | G27: 1 | N27: 1
A28: Russia | B28: 1 | N28: 1
A29: Deer velvet (dried) | B29: 1 | N29: 1
A30: IP SHPILEKOV ALEXEY MIKHAILOVICH | B30: 1 | N30: 1
A31: Grand Total | B31: 4 | C31: 2 | D31: 12 | E31: 11 | F31: 5 | G31: 4 | N31: 38

Sheet import list
A1: Company list for velvet imported as a food | H1: 홈 > 안전정보 > 제품 및 업체검색 > 수입식품조회 (mfds.go.kr) | J1: https://impfood.mfds.go.kr/CFCCC01F01
A2: Year | B2: Month | C2: Day | D2: Importer | E2: Translation of type | F2: Country of origin | G2: Country of export | H2: Importer (Korean) | I2: Product name (Korean) | J2: Product name (English) | K2: Product type (Korean) | L2: Exporter (English) | M2: Date | N2: Expire date start from | O2: Country of origin (KR) | P2: Country of export (KR)
A3: =YEAR(M3) -> 2026 | B3: =TEXT(M3,"mm") -> 06 | C3: =TEXT(M3,"dd") -> 29 | D3: =VLOOKUP(H3,'Names for Vlookup'!$B$26:$C$94,2,FALSE) -> Chunho N Care | E3: =VLOOKUP(K3,'Names for Vlookup'!$B$8:$C$21,2,FALSE) -> Deer velvet (dried) | F3: =VLOOKUP(O3,'Names for Vlookup'!$B$2:$C$5,2,FALSE) -> New Zealand | G3: =VLOOKUP(P3,'Names for Vlookup'!$B$2:$C$5,2,FALSE) -> New Zealand | H3: (주)천호엔케어 | I3: 녹용 | J3: DEER HORN | K3: 녹용(건조) | L3: STREAMLANDS EXPORTS NZ LTD | M3: 2026-06-29 | N3: - | O3: 뉴질랜드 | P3: 뉴질랜드
A4: =YEAR(M4) -> 2026 | B4: =TEXT(M4,"mm") -> 06 | C4: =TEXT(M4,"dd") -> 17 | D4: =VLOOKUP(H4,'Names for Vlookup'!$B$26:$C$94,2,FALSE) -> Eryong Pharm. | E4: =VLOOKUP(K4,'Names for Vlookup'!$B$8:$C$21,2,FALSE) -> Deer velvet (frozen) | F4: =VLOOKUP(O4,'Names for Vlookup'!$B$2:$C$5,2,FALSE) -> New Zealand | G4: =VLOOKUP(P4,'Names for Vlookup'!$B$2:$C$5,2,FALSE) -> New Zealand | H4: 주식회사 이룡제약 | I4: 생녹용(냉동) | J4: FROZEN DEER VELVET | K4: 생녹용(냉동) | L4: ORIENTAL DEER HOLDINGS LIMITED | M4: 2026-06-17 | N4: - | O4: 뉴질랜드 | P4: 뉴질랜드
A5: =YEAR(M5) -> 2026 | B5: =TEXT(M5,"mm") -> 06 | C5: =TEXT(M5,"dd") -> 04 | D5: =VLOOKUP(H5,'Names for Vlookup'!$B$26:$C$94,2,FALSE) -> Bibong Herb | E5: =VLOOKUP(K5,'Names for Vlookup'!$B$8:$C$21,2,FALSE) -> Deer velvet (dried) | F5: =VLOOKUP(O5,'Names for Vlookup'!$B$2:$C$5,2,FALSE) -> New Zealand | G5: =VLOOKUP(P5,'Names for Vlookup'!$B$2:$C$5,2,FALSE) -> New Zealand | H5: 주식회사 비봉허브 | I5: 녹용 | J5: DEER HORN | K5: 녹용(건조) | L5: VEXCO LIMITED | M5: 2026-06-04 | N5: - | O5: 뉴질랜드 | P5: 뉴질랜드
A6: =YEAR(M6) -> 2026 | B6: =TEXT(M6,"mm") -> 06 | C6: =TEXT(M6,"dd") -> 04 | D6: =VLOOKUP(H6,'Names for Vlookup'!$B$26:$C$94,2,FALSE) -> KNC Deertrade | E6: =VLOOKUP(K6,'Names for Vlookup'!$B$8:$C$21,2,FALSE) -> Deer velvet (dried) | F6: =VLOOKUP(O6,'Names for Vlookup'!$B$2:$C$5,2,FALSE) -> New Zealand | G6: =VLOOKUP(P6,'Names for Vlookup'!$B$2:$C$5,2,FALSE) -> China | H6: (주)케이앤씨디어트레이드 | I6: 녹용(건조) | J6: DRIED RED DEER VELVET ANTLER | K6: 녹용(건조) | L6: DALIAN CHANG LU DEER INDUSTRY CO., LTD | M6: 2026-06-04 | N6: - | O6: 뉴질랜드 | P6: 중국
A7: =YEAR(M7) -> 2026 | B7: =TEXT(M7,"mm") -> 05 | C7: =TEXT(M7,"dd") -> 29 | D7: =VLOOKUP(H7,'Names for Vlookup'!$B$26:$C$94,2,FALSE) -> KNC Deertrade | E7: =VLOOKUP(K7,'Names for Vlookup'!$B$8:$C$21,2,FALSE) -> Deer velvet (frozen) | F7: =VLOOKUP(O7,'Names for Vlookup'!$B$2:$C$5,2,FALSE) -> New Zealand | G7: =VLOOKUP(P7,'Names for Vlookup'!$B$2:$C$5,2,FALSE) -> New Zealand | H7: (주)케이앤씨디어트레이드 | I7: 생녹용 | J7: FROZEN RED DEER VELVET ANTLER | K7: 생녹용(냉동) | L7: UB BIO LIMITED | M7: 46171 | N7: 2026-04-10 ~ | O7: 뉴질랜드 | P7: 뉴질랜드
A8: =YEAR(M8) -> 2026 | B8: =TEXT(M8,"mm") -> 05 | C8: =TEXT(M8,"dd") -> 27 | D8: =VLOOKUP(H8,'Names for Vlookup'!$B$26:$C$94,2,FALSE) -> KNC Deertrade | E8: =VLOOKUP(K8,'Names for Vlookup'!$B$8:$C$21,2,FALSE) -> Deer velvet (dried) | F8: =VLOOKUP(O8,'Names for Vlookup'!$B$2:$C$5,2,FALSE) -> New Zealand | G8: =VLOOKUP(P8,'Names for Vlookup'!$B$2:$C$5,2,FALSE) -> China | H8: (주)케이앤씨디어트레이드 | I8: 녹용(건조) | J8: DRIED RED DEER VELVET ANTLER | K8: 녹용(건조) | L8: DALIAN CHANG LU DEER INDUSTRY CO., LTD | M8: 46169 | N8: - | O8: 뉴질랜드 | P8: 중국
A9: =YEAR(M9) -> 2026 | B9: =TEXT(M9,"mm") -> 05 | C9: =TEXT(M9,"dd") -> 19 | D9: =VLOOKUP(H9,'Names for Vlookup'!$B$26:$C$94,2,FALSE) -> YW International | E9: =VLOOKUP(K9,'Names for Vlookup'!$B$8:$C$21,2,FALSE) -> Deer velvet (frozen) | F9: =VLOOKUP(O9,'Names for Vlookup'!$B$2:$C$5,2,FALSE) -> New Zealand | G9: =VLOOKUP(P9,'Names for Vlookup'!$B$2:$C$5,2,FALSE) -> New Zealand | H9: 와이더블유 인터내셔날 | I9: 냉동녹용 | J9: FROZEN WHOLE DEER VELVET ANTLER | K9: 생녹용(냉동) | L9: ROKLAND CORPORATION LIMITED | M9: 46161 | N9: - | O9: 뉴질랜드 | P9: 뉴질랜드
A10: =YEAR(M10) -> 2026 | B10: =TEXT(M10,"mm") -> 05 | C10: =TEXT(M10,"dd") -> 13 | D10: =VLOOKUP(H10,'Names for Vlookup'!$B$26:$C$94,2,FALSE) -> Eryong Pharm. | E10: =VLOOKUP(K10,'Names for Vlookup'!$B$8:$C$21,2,FALSE) -> Deer velvet (dried) | F10: =VLOOKUP(O10,'Names for Vlookup'!$B$2:$C$5,2,FALSE) -> China | G10: =VLOOKUP(P10,'Names for Vlookup'!$B$2:$C$5,2,FALSE) -> China | H10: 주식회사 이룡제약 | I10: 녹용 | J10: DEER HORN | K10: 녹용(건조) | L10: TIELING AOLU TRADE CO.,LTD | M10: 46155 | N10: - | O10: 중국 | P10: 중국
A11: =YEAR(M11) -> 2026 | B11: =TEXT(M11,"mm") -> 05 | C11: =TEXT(M11,"dd") -> 08 | D11: =VLOOKUP(H11,'Names for Vlookup'!$B$26:$C$94,2,FALSE) -> OnBio | E11: =VLOOKUP(K11,'Names for Vlookup'!$B$8:$C$21,2,FALSE) -> Deer velvet (dried) | F11: =VLOOKUP(O11,'Names for Vlookup'!$B$2:$C$5,2,FALSE) -> New Zealand | G11: =VLOOKUP(P11,'Names for Vlookup'!$B$2:$C$5,2,FALSE) -> China | H11: 온바이오 | I11: 녹용(건조) | J11: DRIED RED DEER VELVET ANTLER | K11: 녹용(건조) | L11: DALIAN F.T.Z. JUNFENG INTERNATIONAL INDUSTRIAL & TRADE CO.,LTD. | M11: 46150 | N11: - | O11: 뉴질랜드 | P11: 중국
A12: =YEAR(M12) -> 2026 | B12: =TEXT(M12,"mm") -> 04 | C12: =TEXT(M12,"dd") -> 17 | D12: =VLOOKUP(H12,'Names for Vlookup'!$B$26:$C$94,2,FALSE) -> Onnuri Bio | E12: =VLOOKUP(K12,'Names for Vlookup'!$B$8:$C$21,2,FALSE) -> Deer velvet (dried) | F12: =VLOOKUP(O12,'Names for Vlookup'!$B$2:$C$5,2,FALSE) -> New Zealand | G12: =VLOOKUP(P12,'Names for Vlookup'!$B$2:$C$5,2,FALSE) -> China | H12: (주)온누리바이오생약 | I12: 녹용 | J12: DEER HORN | K12: 녹용(건조) | L12: TIELING AOLU TRADE CO.,LTD | M12: 46129 | N12: - | O12: 뉴질랜드 | P12: 중국
A13: =YEAR(M13) -> 2026 | B13: =TEXT(M13,"mm") -> 04 | C13: =TEXT(M13,"dd") -> 10 | D13: =VLOOKUP(H13,'Names for Vlookup'!$B$26:$C$94,2,FALSE) -> WooSung (Mr Bang) | E13: =VLOOKUP(K13,'Names for Vlookup'!$B$8:$C$21,2,FALSE) -> Deer velvet (dried) | F13: =VLOOKUP(O13,'Names for Vlookup'!$B$2:$C$5,2,FALSE) -> New Zealand | G13: =VLOOKUP(P13,'Names for Vlookup'!$B$2:$C$5,2,FALSE) -> China | H13: (주)우성생약 | I13: 녹용(건조) | J13: DRIED RED DEER VELVET ANTLER | K13: 녹용(건조) | L13: XIFENG MINHE DEER PRODUCTS CO.,LTD | M13: 46122 | N13: - | O13: 뉴질랜드 | P13: 중국
A14: =YEAR(M14) -> 2026 | B14: =TEXT(M14,"mm") -> 04 | C14: =TEXT(M14,"dd") -> 07 | D14: =VLOOKUP(H14,'Names for Vlookup'!$B$26:$C$94,2,FALSE) -> WooSung (Mr Bang) | E14: =VLOOKUP(K14,'Names for Vlookup'!$B$8:$C$21,2,FALSE) -> Deer velvet (dried) | F14: =VLOOKUP(O14,'Names for Vlookup'!$B$2:$C$5,2,FALSE) -> New Zealand | G14: =VLOOKUP(P14,'Names for Vlookup'!$B$2:$C$5,2,FALSE) -> China | H14: (주)우성생약 | I14: 녹용(건조) | J14: DRIED RED DEER VELVET ANTLER | K14: 녹용(건조) | L14: XIFENG MINHE DEER PRODUCTS CO.,LTD | M14: 46119 | N14: - | O14: 뉴질랜드 | P14: 중국
A15: =YEAR(M15) -> 2026 | B15: =TEXT(M15,"mm") -> 04 | C15: =TEXT(M15,"dd") -> 07 | D15: =VLOOKUP(H15,'Names for Vlookup'!$B$26:$C$94,2,FALSE) -> GaOn Pharm | E15: =VLOOKUP(K15,'Names for Vlookup'!$B$8:$C$21,2,FALSE) -> Deer velvet (frozen) | F15: =VLOOKUP(O15,'Names for Vlookup'!$B$2:$C$5,2,FALSE) -> New Zealand | G15: =VLOOKUP(P15,'Names for Vlookup'!$B$2:$C$5,2,FALSE) -> New Zealand | H15: 주식회사 가온제약 | I15: 냉동녹용 | J15: FROZEN RED DEER VELVET ANTLER | K15: 생녹용(냉동) | L15: CK IMPORT-EXPORT COMPANY NZ LIMITED | M15: 46119 | N15: - | O15: 뉴질랜드 | P15: 뉴질랜드
A16: =YEAR(M16) -> 2026 | B16: =TEXT(M16,"mm") -> 04 | C16: =TEXT(M16,"dd") -> 03 | D16: =VLOOKUP(H16,'Names for Vlookup'!$B$26:$C$94,2,FALSE) -> KNC Deertrade | E16: =VLOOKUP(K16,'Names for Vlookup'!$B$8:$C$21,2,FALSE) -> Deer velvet (frozen) | F16: =VLOOKUP(O16,'Names for Vlookup'!$B$2:$C$5,2,FALSE) -> New Zealand | G16: =VLOOKUP(P16,'Names for Vlookup'!$B$2:$C$5,2,FALSE) -> New Zealand | H16: (주)케이앤씨디어트레이드 | I16: 생녹용 | J16: WHOLE FROZEN DEER VELVET | K16: 생녹용(냉동) | L16: ROKLAND CORPORATION LIMITED | M16: 46115 | N16: 2026-02-25 ~ | O16: 뉴질랜드 | P16: 뉴질랜드
A17: =YEAR(M17) -> 2026 | B17: =TEXT(M17,"mm") -> 04 | C17: =TEXT(M17,"dd") -> 03 | D17: =VLOOKUP(H17,'Names for Vlookup'!$B$26:$C$94,2,FALSE) -> HwaYong Pharm. | E17: =VLOOKUP(K17,'Names for Vlookup'!$B$8:$C$21,2,FALSE) -> Deer velvet (frozen) | F17: =VLOOKUP(O17,'Names for Vlookup'!$B$2:$C$5,2,FALSE) -> New Zealand | G17: =VLOOKUP(P17,'Names for Vlookup'!$B$2:$C$5,2,FALSE) -> New Zealand | H17: 화용제약 | I17: 생녹용(냉동) | J17: FROZEN DEER HORN | K17: 생녹용(냉동) | L17: CK IMPORT EXPORT CO.(NZ) LTD | M17: 46115 | N17: - | O17: 뉴질랜드 | P17: 뉴질랜드
A18: =YEAR(M18) -> 2026 | B18: =TEXT(M18,"mm") -> 03 | C18: =TEXT(M18,"dd") -> 25 | D18: =VLOOKUP(H18,'Names for Vlookup'!$B$26:$C$94,2,FALSE) -> OnBio | E18: =VLOOKUP(K18,'Names for Vlookup'!$B$8:$C$21,2,FALSE) -> Deer velvet (frozen) | F18: =VLOOKUP(O18,'Names for Vlookup'!$B$2:$C$5,2,FALSE) -> New Zealand | G18: =VLOOKUP(P18,'Names for Vlookup'!$B$2:$C$5,2,FALSE) -> New Zealand | H18: 온바이오 | I18: 생녹용(냉동) | J18: FROZEN DEER VELVET | K18: 생녹용(냉동) | L18: YIK LUNG TONG(NZ) INTERNAIONAL LIMITED | M18: 46106 | N18: - | O18: 뉴질랜드 | P18: 뉴질랜드
... A26: =YEAR(M26) -> 2026 | B26: =TEXT(M26,"mm") -> 04 | C26: =TEXT(M26,"dd") -> 07 | D26: =VLOOKUP(H26,'Names for Vlookup'!$B$26:$C$94,2,FALSE) -> GaOn Pharm | E26: =VLOOKUP(K26,'Names for Vlookup'!$B$8:$C$21,2,FALSE) -> Deer velvet (frozen) | F26: =VLOOKUP(O26,'Names for Vlookup'!$B$2:$C$5,2,FALSE) -> New Zealand | G26: =VLOOKUP(P26,'Names for Vlookup'!$B$2:$C$5,2,FALSE) -> New Zealand | H26: 주식회사 가온제약 | I26: 냉동녹용 | J26: FROZEN RED DEER VELVET ANTLER | K26: 생녹용(냉동) | L26: CK IMPORT-EXPORT COMPANY NZ LIMITED | M26: 46119 | N26: - | O26: 뉴질랜드 | P26: 뉴질랜드
A27: =YEAR(M27) -> 2026 | B27: =TEXT(M27,"mm") -> 04 | C27: =TEXT(M27,"dd") -> 03 | D27: =VLOOKUP(H27,'Names for Vlookup'!$B$26:$C$94,2,FALSE) -> KNC Deertrade | E27: =VLOOKUP(K27,'Names for Vlookup'!$B$8:$C$21,2,FALSE) -> Deer velvet (frozen) | F27: =VLOOKUP(O27,'Names for Vlookup'!$B$2:$C$5,2,FALSE) -> New Zealand | G27: =VLOOKUP(P27,'Names for Vlookup'!$B$2:$C$5,2,FALSE) -> New Zealand | H27: (주)케이앤씨디어트레이드 | I27: 생녹용 | J27: WHOLE FROZEN DEER VELVET | K27: 생녹용(냉동) | L27: ROKLAND CORPORATION LIMITED | M27: 2026-04-03 | N27: 2026-02-25 ~ | O27: 뉴질랜드 | P27: 뉴질랜드
A28: =YEAR(M28) -> 2026 | B28: =TEXT(M28,"mm") -> 04 | C28: =TEXT(M28,"dd") -> 03 | D28: =VLOOKUP(H28,'Names for Vlookup'!$B$26:$C$94,2,FALSE) -> HwaYong Pharm. | E28: =VLOOKUP(K28,'Names for Vlookup'!$B$8:$C$21,2,FALSE) -> Deer velvet (frozen) | F28: =VLOOKUP(O28,'Names for Vlookup'!$B$2:$C$5,2,FALSE) -> New Zealand | G28: =VLOOKUP(P28,'Names for Vlookup'!$B$2:$C$5,2,FALSE) -> New Zealand | H28: 화용제약 | I28: 생녹용(냉동) | J28: FROZEN DEER HORN | K28: 생녹용(냉동) | L28: CK IMPORT EXPORT CO.(NZ) LTD | M28: 2026-04-03 | N28: - | O28: 뉴질랜드 | P28: 뉴질랜드
A29: =YEAR(M29) -> 2026 | B29: =TEXT(M29,"mm") -> 03 | C29: =TEXT(M29,"dd") -> 25 | D29: =VLOOKUP(H29,'Names for Vlookup'!$B$26:$C$94,2,FALSE) -> OnBio | E29: =VLOOKUP(K29,'Names for Vlookup'!$B$8:$C$21,2,FALSE) -> Deer velvet (frozen) | F29: =VLOOKUP(O29,'Names for Vlookup'!$B$2:$C$5,2,FALSE) -> New Zealand | G29: =VLOOKUP(P29,'Names for Vlookup'!$B$2:$C$5,2,FALSE) -> New Zealand | H29: 온바이오 | I29: 생녹용(냉동) | J29: FROZEN DEER VELVET | K29: 생녹용(냉동) | L29: YIK LUNG TONG(NZ) INTERNAIONAL LIMITED | M29: 2026-03-25 | N29: - | O29: 뉴질랜드 | P29: 뉴질랜드
A30: =YEAR(M30) -> 2026 | B30: =TEXT(M30,"mm") -> 03 | C30: =TEXT(M30,"dd") -> 17 | D30: =VLOOKUP(H30,'Names for Vlookup'!$B$26:$C$94,2,FALSE) -> KNC Deertrade | E30: =VLOOKUP(K30,'Names for Vlookup'!$B$8:$C$21,2,FALSE) -> Deer velvet (frozen) | F30: =VLOOKUP(O30,'Names for Vlookup'!$B$2:$C$5,2,FALSE) -> New Zealand | G30: =VLOOKUP(P30,'Names for Vlookup'!$B$2:$C$5,2,FALSE) -> New Zealand | H30: (주)케이앤씨디어트레이드 | I30: 생녹용 | J30: FROZEN RED DEER VELVET ANTLER | K30: 생녹용(냉동) | L30: PROVELCO LTD | M30: 46098 | N30: 2026-01-21 ~ | O30: 뉴질랜드 | P30: 뉴질랜드
A31: =YEAR(M31) -> 2026 | B31: =TEXT(M31,"mm") -> 03 | C31: =TEXT(M31,"dd") -> 16 | D31: =VLOOKUP(H31,'Names for Vlookup'!$B$26:$C$94,2,FALSE) -> Bio Dot (Han Dong Herb) | E31: =VLOOKUP(K31,'Names for Vlookup'!$B$8:$C$21,2,FALSE) -> Deer velvet (frozen) | F31: =VLOOKUP(O31,'Names for Vlookup'!$B$2:$C$5,2,FALSE) -> New Zealand | G31: =VLOOKUP(P31,'Names for Vlookup'!$B$2:$C$5,2,FALSE) -> New Zealand | H31: (주)바이오닷 | I31: 생녹용 | J31: FROZEN RED DEER VELVET ANTLER | K31: 생녹용(냉동) | L31: C K IMPORT EXPORT CO (NZ) LTD | M31: 46097 | N31: 2026-01-27 ~ 2029-01-27 | O31: 뉴질랜드 | P31: 뉴질랜드
A32: =YEAR(M32) -> 2026 | B32: =TEXT(M32,"mm") -> 03 | C32: =TEXT(M32,"dd") -> 12 | D32: =VLOOKUP(H32,'Names for Vlookup'!$B$26:$C$94,2,FALSE) -> YW International | E32: =VLOOKUP(K32,'Names for Vlookup'!$B$8:$C$21,2,FALSE) -> Deer velvet (frozen) | F32: =VLOOKUP(O32,'Names for Vlookup'!$B$2:$C$5,2,FALSE) -> New Zealand | G32: =VLOOKUP(P32,'Names for Vlookup'!$B$2:$C$5,2,FALSE) -> New Zealand | H32: 와이더블유 인터내셔날 | I32: 냉동녹용 | J32: FROZEN WHOLE DEER VELVET ANTLER | K32: 생녹용(냉동) | L32: ROKLAND CORPORATION LIMITED | M32: 46093 | N32: - | O32: 뉴질랜드 | P32: 뉴질랜드
A33: =YEAR(M33) -> 2026 | B33: =TEXT(M33,"mm") -> 03 | C33: =TEXT(M33,"dd") -> 12 | D33: =VLOOKUP(H33,'Names for Vlookup'!$B$26:$C$94,2,FALSE) -> KGC | E33: =VLOOKUP(K33,'Names for Vlookup'!$B$8:$C$21,2,FALSE) -> Deer velvet (frozen) | F33: =VLOOKUP(O33,'Names for Vlookup'!$B$2:$C$5,2,FALSE) -> New Zealand | G33: =VLOOKUP(P33,'Names for Vlookup'!$B$2:$C$5,2,FALSE) -> New Zealand | H33: (주)한국인삼공사 | I33: 생녹용(냉동) | J33: FROZEN RED DEER VELVET ANTLER | K33: 생녹용(냉동) | L33: PAREX INTERNATIONAL LTD | M33: 46093 | N33: - | O33: 뉴질랜드 | P33: 뉴질랜드
A34: =YEAR(M34) -> 2026 | B34: =TEXT(M34,"mm") -> 03 | C34: =TEXT(M34,"dd") -> 11 | D34: =VLOOKUP(H34,'Names for Vlookup'!$B$26:$C$94,2,FALSE) -> Yujin Trade | E34: =VLOOKUP(K34,'Names for Vlookup'!$B$8:$C$21,2,FALSE) -> Deer velvet (dried) | F34: =VLOOKUP(O34,'Names for Vlookup'!$B$2:$C$5,2,FALSE) -> New Zealand | G34: =VLOOKUP(P34,'Names for Vlookup'!$B$2:$C$5,2,FALSE) -> China | H34: 유진통상 | I34: 녹용(건조) | J34: DRIED RED DEER VELVET ANTLER | K34: 녹용(건조) | L34: DALIAN HENGLU DEER INDUSTRY CO LTD | M34: 46092 | N34: - | O34: 뉴질랜드 | P34: 중국
A35: =YEAR(M35) -> 2026 | B35: =TEXT(M35,"mm") -> 02 | C35: =TEXT(M35,"dd") -> 20 | D35: =VLOOKUP(H35,'Names for Vlookup'!$B$26:$C$94,2,FALSE) -> Eryong Pharm. | E35: =VLOOKUP(K35,'Names for Vlookup'!$B$8:$C$21,2,FALSE) -> Deer velvet (frozen) | F35: =VLOOKUP(O35,'Names for Vlookup'!$B$2:$C$5,2,FALSE) -> New Zealand | G35: =VLOOKUP(P35,'Names for Vlookup'!$B$2:$C$5,2,FALSE) -> New Zealand | H35: 주식회사 이룡제약 | I35: 생녹용(냉동) | J35: FROZEN DEER VELVET | K35: 생녹용(냉동) | L35: YIK LUNG TONG(NZ) INTERNAIONAL LIMITED | M35: 46073 | N35: - | O35: 뉴질랜드 | P35: 뉴질랜드
A36: =YEAR(M36) -> 2026 | B36: =TEXT(M36,"mm") -> 02 | C36: =TEXT(M36,"dd") -> 05 | D36: =VLOOKUP(H36,'Names for Vlookup'!$B$26:$C$94,2,FALSE) -> HwaYong Pharm. | E36: =VLOOKUP(K36,'Names for Vlookup'!$B$8:$C$21,2,FALSE) -> Deer velvet (frozen) | F36: =VLOOKUP(O36,'Names for Vlookup'!$B$2:$C$5,2,FALSE) -> New Zealand | G36: =VLOOKUP(P36,'Names for Vlookup'!$B$2:$C$5,2,FALSE) -> New Zealand | H36: 화용제약 | I36: 생녹용(냉동) | J36: FROZEN DEER HORN | K36: 생녹용(냉동) | L36: CK IMPORT EXPORT CO.(NZ) LTD | M36: 46058 | N36: - | O36: 뉴질랜드 | P36: 뉴질랜드
A37: =YEAR(M37) -> 2026 | B37: =TEXT(M37,"mm") -> 01 | C37: =TEXT(M37,"dd") -> 27 | D37: =VLOOKUP(H37,'Names for Vlookup'!$B$26:$C$94,2,FALSE) -> KNC Deertrade | E37: =VLOOKUP(K37,'Names for Vlookup'!$B$8:$C$21,2,FALSE) -> Deer velvet (dried) | F37: =VLOOKUP(O37,'Names for Vlookup'!$B$2:$C$5,2,FALSE) -> New Zealand | G37: =VLOOKUP(P37,'Names for Vlookup'!$B$2:$C$5,2,FALSE) -> China | H37: (주)케이앤씨디어트레이드 | I37: 녹용(건조) | J37: DRIED RED DEER VELVET ANTLER | K37: 녹용(건조) | L37: DALIAN F.T.Z. JUNFENG INTERNATIONAL INDUSTRIAL & TRADE CO.,LTD. | M37: 46049 | N37: - | O37: 뉴질랜드 | P37: 중국
A38: =YEAR(M38) -> 2026 | B38: =TEXT(M38,"mm") -> 01 | C38: =TEXT(M38,"dd") -> 15 | D38: =VLOOKUP(H38,'Names for Vlookup'!$B$26:$C$94,2,FALSE) -> YW International | E38: =VLOOKUP(K38,'Names for Vlookup'!$B$8:$C$21,2,FALSE) -> Deer velvet (frozen) | F38: =VLOOKUP(O38,'Names for Vlookup'!$B$2:$C$5,2,FALSE) -> New Zealand | G38: =VLOOKUP(P38,'Names for Vlookup'!$B$2:$C$5,2,FALSE) -> New Zealand | H38: 와이더블유 인터내셔날 | I38: 냉동녹용 | J38: FROZEN WHOLE DEER VELVET ANTLER | K38: 생녹용(냉동) | L38: ROKLAND CORPORATION LIMITED | M38: 46037 | N38: - | O38: 뉴질랜드 | P38: 뉴질랜드
A39: =YEAR(M39) -> 2026 | B39: =TEXT(M39,"mm") -> 01 | C39: =TEXT(M39,"dd") -> 09 | D39: =VLOOKUP(H39,'Names for Vlookup'!$B$26:$C$94,2,FALSE) -> Geonhyang Pharm. | E39: =VLOOKUP(K39,'Names for Vlookup'!$B$8:$C$21,2,FALSE) -> Deer velvet (dried) | F39: =VLOOKUP(O39,'Names for Vlookup'!$B$2:$C$5,2,FALSE) -> Russia | G39: =VLOOKUP(P39,'Names for Vlookup'!$B$2:$C$5,2,FALSE) -> Russia | H39: 건향제약주식회사 | I39: 녹용(건조) | J39: DEER HORNS VELVET ANTLER | K39: 녹용(건조) | L39: IP SHPILEKOV ALEXEY MIKHAILOVICH | M39: 46031 | N39: - | O39: 러시아 | P39: 러시아
A40: =YEAR(M40) -> 2026 | B40: =TEXT(M40,"mm") -> 01 | C40: =TEXT(M40,"dd") -> 09 | D40: =VLOOKUP(H40,'Names for Vlookup'!$B$26:$C$94,2,FALSE) -> Bio Dot (Han Dong Herb) | E40: =VLOOKUP(K40,'Names for Vlookup'!$B$8:$C$21,2,FALSE) -> Deer velvet (frozen) | F40: =VLOOKUP(O40,'Names for Vlookup'!$B$2:$C$5,2,FALSE) -> New Zealand | G40: =VLOOKUP(P40,'Names for Vlookup'!$B$2:$C$5,2,FALSE) -> New Zealand | H40: (주)바이오닷 | I40: 생녹용 | J40: FROZEN RED DEER VELVET ANTLER | K40: 생녹용(냉동) | L40: C K IMPORT EXPORT CO (NZ) LTD | M40: 46031 | N40: 2025-12-09 ~ 2028-12-09 | O40: 뉴질랜드 | P40: 뉴질랜드
A41: =YEAR(M41) -> 2025 | B41: =TEXT(M41,"mm") -> 12 | C41: =TEXT(M41,"dd") -> 15 | D41: =VLOOKUP(H41,'Names for Vlookup'!$B$26:$C$94,2,FALSE) -> HwaYong Pharm. | E41: =VLOOKUP(K41,'Names for Vlookup'!$B$8:$C$21,2,FALSE) -> Deer velvet (dried) | F41: =VLOOKUP(O41,'Names for Vlookup'!$B$2:$C$5,2,FALSE) -> New Zealand | G41: =VLOOKUP(P41,'Names for Vlookup'!$B$2:$C$5,2,FALSE) -> China | H41: 화용제약 | I41: 녹용 | J41: DEER HORN | K41: 녹용(건조) | L41: DALIAN SHENG EN DEER PRODUCTS CO LTD | M41: 46006 | N41: - | O41: 뉴질랜드 | P41: 중국
... A53: =YEAR(M53) -> 2025 | B53: =TEXT(M53,"mm") -> 10 | C53: =TEXT(M53,"dd") -> 23 | D53: =VLOOKUP(H53,'Names for Vlookup'!$B$26:$C$94,2,FALSE) -> KNC Deertrade | E53: =VLOOKUP(K53,'Names for Vlookup'!$B$8:$C$21,2,FALSE) -> Deer velvet (frozen) | F53: =VLOOKUP(O53,'Names for Vlookup'!$B$2:$C$5,2,FALSE) -> New Zealand | G53: =VLOOKUP(P53,'Names for Vlookup'!$B$2:$C$5,2,FALSE) -> New Zealand | H53: (주)케이앤씨디어트레이드 | I53: 생녹용 | J53: FROZEN RED DEER VELVET ANTLER | K53: 생녹용(냉동) | L53: ORIENTAL DEER HOLDINGS LIMITED | M53: 45953 | N53: 2025-09-08 ~ | O53: 뉴질랜드 | P53: 뉴질랜드
A54: =YEAR(M54) -> 2025 | B54: =TEXT(M54,"mm") -> 09 | C54: =TEXT(M54,"dd") -> 23 | D54: =VLOOKUP(H54,'Names for Vlookup'!$B$26:$C$94,2,FALSE) -> KGC | E54: =VLOOKUP(K54,'Names for Vlookup'!$B$8:$C$21,2,FALSE) -> Deer velvet (dried) | F54: =VLOOKUP(O54,'Names for Vlookup'!$B$2:$C$5,2,FALSE) -> New Zealand | G54: =VLOOKUP(P54,'Names for Vlookup'!$B$2:$C$5,2,FALSE) -> New Zealand | H54: (주)한국인삼공사 | I54: 녹용(건조) | J54: DRIED RED DEER VELVET ANTLER | K54: 녹용(건조) | L54: PAREX INTERNATIONAL LTD | M54: 2025-09-23 | N54: - | O54: 뉴질랜드 | P54: 뉴질랜드
A55: =YEAR(M55) -> 2025 | B55: =TEXT(M55,"mm") -> 09 | C55: =TEXT(M55,"dd") -> 23 | D55: =VLOOKUP(H55,'Names for Vlookup'!$B$26:$C$94,2,FALSE) -> OnBio | E55: =VLOOKUP(K55,'Names for Vlookup'!$B$8:$C$21,2,FALSE) -> Deer velvet (dried) | F55: =VLOOKUP(O55,'Names for Vlookup'!$B$2:$C$5,2,FALSE) -> New Zealand | G55: =VLOOKUP(P55,'Names for Vlookup'!$B$2:$C$5,2,FALSE) -> China | H55: 온바이오 | I55: 녹용(건조) | J55: DRIED RED DEER VELVET ANTLER | K55: 녹용(건조) | L55: DALIAN F.T.Z. JUNFENG INTERNATIONAL INDUSTRIAL & TRADE CO.,LTD. | M55: 2025-09-23 | N55: - | O55: 뉴질랜드 | P55: 중국
A56: =YEAR(M56) -> 2025 | B56: =TEXT(M56,"mm") -> 09 | C56: =TEXT(M56,"dd") -> 09 | D56: =VLOOKUP(H56,'Names for Vlookup'!$B$26:$C$94,2,FALSE) -> KGC | E56: =VLOOKUP(K56,'Names for Vlookup'!$B$8:$C$21,2,FALSE) -> Deer velvet (dried) | F56: =VLOOKUP(O56,'Names for Vlookup'!$B$2:$C$5,2,FALSE) -> New Zealand | G56: =VLOOKUP(P56,'Names for Vlookup'!$B$2:$C$5,2,FALSE) -> New Zealand | H56: (주)한국인삼공사 | I56: 녹용(건조) | J56: DRIED RED DEER VELVET ANTLER | K56: 녹용(건조) | L56: ORIENTAL DEER HOLDINGS LIMITED | M56: 2025-09-09 | N56: - | O56: 뉴질랜드 | P56: 뉴질랜드
A57: =YEAR(M57) -> 2025 | B57: =TEXT(M57,"mm") -> 09 | C57: =TEXT(M57,"dd") -> 02 | D57: =VLOOKUP(H57,'Names for Vlookup'!$B$26:$C$94,2,FALSE) -> Hyangna Bio | E57: =VLOOKUP(K57,'Names for Vlookup'!$B$8:$C$21,2,FALSE) -> Deer velvet (dried) | F57: =VLOOKUP(O57,'Names for Vlookup'!$B$2:$C$5,2,FALSE) -> New Zealand | G57: =VLOOKUP(P57,'Names for Vlookup'!$B$2:$C$5,2,FALSE) -> China | H57: 향나바이오 주식회사 | I57: 녹용 | J57: DEER HORN | K57: 녹용(건조) | L57: DALIAN SHENG EN DEER PRODUCTS CO LTD | M57: 2025-09-02 | N57: - | O57: 뉴질랜드 | P57: 중국
A58: =YEAR(M58) -> 2025 | B58: =TEXT(M58,"mm") -> 08 | C58: =TEXT(M58,"dd") -> 29 | D58: =VLOOKUP(H58,'Names for Vlookup'!$B$26:$C$94,2,FALSE) -> Yujin Trade | E58: =VLOOKUP(K58,'Names for Vlookup'!$B$8:$C$21,2,FALSE) -> Deer velvet (dried) | F58: =VLOOKUP(O58,'Names for Vlookup'!$B$2:$C$5,2,FALSE) -> New Zealand | G58: =VLOOKUP(P58,'Names for Vlookup'!$B$2:$C$5,2,FALSE) -> China | H58: 유진통상 | I58: 녹용(건조) | J58: DEER HORNS VELVET ANTLER | K58: 녹용(건조) | L58: DALIAN HENGLU DEER INDUSTRY CO LTD | M58: 2025-08-29 | N58: - | O58: 뉴질랜드 | P58: 중국
...

Sheet Names for Vlookup
B2: 뉴질랜드 | C2: New Zealand
B3: 러시아 | C3: Russia
B4: 홍콩 | C4: Hong Kong
B5: 중국 | C5: China
B7: Product name (Korean) | C7: Translation
B8: 건녹용 | C8: Deer velvet (dried)
B9: 건조녹용 | C9: Deer velvet (dried)
B10: 건조녹용(전지) | C10: Dried deer velvet (whole stick)
B11: 건조절편녹용 | C11: Dried sliced deer velvet
B12: 기타 동물성가공식품 | C12: Animal based processed food
B13: 냉동녹용 | C13: Deer velvet (frozen)
B14: 녹각 | C14: Hard antlers
... B181: UIMON CO.,LTD | C181: Russia
